Workbook
Name Contractor_Detail: "`"
Name subc_contr_folder_path: config!$B$1

Sheet data
A1: # | B1: Item no | C1: Contract order no | D1: Contract ID | E1: Contract no | F1: Title | H1: Call | I1: WP | J1: Employee | K1: Status | L1: Record no | M1: Record person | N1: Plate no | P1: Type | Q1: Brand/Model | R1: Department | S1: Folder Name | T1: x | U1: Folder | V1: IPC's | W1: Log | X1: IPC pdf | Y1: IPC # to open | Z1: Last IPC # | AA1: x | AB1: Notes | AC1: Record sheet given | AD1: Record sheet received | AE1: Calculate | AF1: Amount log | AG1: Sent | AH1: Subc. Signature | AI1: Printed | AJ1: Discipline signature | AK1: IPC chief signature | AL1: TO chief signature | AM1: Deputy PM signature | AN1: Site Manager | AO1: PM signature | AP1: Stamp | AQ1: Cover to Bookkeeper | AR1: Foldering
A2: 1 | B2: =COUNTIF(INDIRECT("D1:D"&ROW()-1),D2)+1 -> 1 | C2: =IF(_xlfn.IFNA(MATCH(D2,$D$1:D1,0),0)=0,MAX($C$1:C1)+1,"") -> 1 | D2: KLN-SPP2-CW-011 | E2: =_xlfn.NUMBERVALUE(RIGHT(D2,3)) -> 11 | F2: CASPIAN ENGINEERING MMC | G2: +994776371714 | H2: {=IF(_xlfn.DROP(_xlfn._TRO_TRAILING(G:G),1)="","",HYPERLINK("tel://"&MID(_xlfn.DROP(_xlfn._TRO_TRAILING(G:G),1),2,100),"📞"))} -> 📞 | I2: {=IF(_xlfn.DROP(_xlfn._TRO_TRAILING(G:G),1)="","",HYPERLINK("https://api.whatsapp.com/send?phone="&MID(_xlfn.DROP(_xlfn._TRO_TRAILING(G:G),1),2,100)&"&text=-","💬"))} -> 💬 | J2: EB | K2: Active | M2: Sadık Boz | R2: QA/QC | S2: 011_Caspian Engineering | U2: =HYPERLINK(subc_contr_folder_path&S2,"Open") -> Open | V2: =HYPERLINK(subc_contr_folder_path&S2&"\ipcs\"&Y2,"Open") -> #VALUE! | W2: =HYPERLINK(subc_contr_folder_path&S2&"\ipcs\"&Y2&"\"&"log.pdf","Open") -> #VALUE! | X2: =HYPERLINK(subc_contr_folder_path&S2&"\ipcs\"&Y2&"\"&E2&"-"&Y2&".pdf","Open") -> #VALUE! | Y2: =IF(Z2="","",Z2) -> #VALUE! | Z2: {=_xlfn.MAXIFS([2]log_ipcs!$D:$D,[2]log_ipcs!$C:$C,_xlfn.NUMBERVALUE(LEFT(_xlfn.DROP(_xlfn._TRO_TRAILING(S:S),1),3)))} -> #VALUE! | AB2: contract scan | AC2: + | AD2: + | AE2: + | AF2: + | AG2: + | AH2: + | AI2: + | AJ2: +
A3: =+A2+1 -> 2 | B3: =COUNTIF(INDIRECT("D1:D"&ROW()-1),D3)+1 -> 1 | C3: =IF(_xlfn.IFNA(MATCH(D3,$D$1:D2,0),0)=0,MAX($C$1:C2)+1,"") -> 2 | D3: KLN-SPP2-EQ-014 | E3: =_xlfn.NUMBERVALUE(RIGHT(D3,3)) -> 14 | F3: HILAL LTD MMC | G3: +994502459043 | H3: 📞 | I3: 💬 | J3: EB | K3: Active | M3: Mesut Fırat | R3: Workshop | S3: 014_Hilal Ltd | U3: =HYPERLINK(subc_contr_folder_path&S3,"Open") -> Open | V3: =HYPERLINK(subc_contr_folder_path&S3&"\ipcs\"&Y3,"Open") -> #VALUE! | W3: =HYPERLINK(subc_contr_folder_path&S3&"\ipcs\"&Y3&"\"&"log.pdf","Open") -> #VALUE! | X3: =HYPERLINK(subc_contr_folder_path&S3&"\ipcs\"&Y3&"\"&E3&"-"&Y3&".pdf","Open") -> #VALUE! | Y3: =IF(Z3="","",Z3) -> #VALUE! | Z3: #VALUE! | AC3: + | AD3: + | AE3: + | AF3: + | AG3: + | AH3: + | AI3: +
A4: =+A3+1 -> 3 | B4: =COUNTIF(INDIRECT("D1:D"&ROW()-1),D4)+1 -> 1 | C4: =IF(_xlfn.IFNA(MATCH(D4,$D$1:D3,0),0)=0,MAX($C$1:C3)+1,"") -> 3 | D4: KLN-SPP2-AA-030 | E4: =_xlfn.NUMBERVALUE(RIGHT(D4,3)) -> 30 | F4: NAR TRANSPORT SERVICES MMC | G4: +994512449400 | H4: 📞 | I4: 💬 | J4: EB | K4: Active | L4: =IF(OR(K4="",N4=""),"",IF(L3="",MAX(L$2:L3),L3)+1) -> 1 | M4: İbrahim Kemik | N4: 99JE233 | R4: Administration | S4: 030_Nar Transport_Ambulance | U4: =HYPERLINK(subc_contr_folder_path&S4,"Open") -> Open | V4: =HYPERLINK(subc_contr_folder_path&S4&"\ipcs\"&Y4,"Open") -> #VALUE! | W4: =HYPERLINK(subc_contr_folder_path&S4&"\ipcs\"&Y4&"\"&"log.pdf","Open") -> #VALUE! | X4: =HYPERLINK(subc_contr_folder_path&S4&"\ipcs\"&Y4&"\"&E4&"-"&Y4&".pdf","Open") -> #VALUE! | Y4: =IF(Z4="","",Z4) -> #VALUE! | Z4: #VALUE! | AC4: + | AD4: + | AE4: + | AF4: +
A5: =+A4+1 -> 4 | B5: =COUNTIF(INDIRECT("D1:D"&ROW()-1),D5)+1 -> 2 | C5: =IF(_xlfn.IFNA(MATCH(D5,$D$1:D4,0),0)=0,MAX($C$1:C4)+1,"") | D5: KLN-SPP2-AA-030 | E5: =_xlfn.NUMBERVALUE(RIGHT(D5,3)) -> 30 | F5: NAR TRANSPORT SERVICES MMC | J5: EB | L5: =IF(OR(K5="",N5=""),"",IF(L4="",MAX(L$2:L4),L4)+1) | N5: 99AS882 | R5: Administration | S5: 030_Nar Transport_Ambulance | Y5: =IF(Z5="","",Z5) -> #VALUE! | Z5: #VALUE!
A6: =+A5+1 -> 5 | B6: =COUNTIF(INDIRECT("D1:D"&ROW()-1),D6)+1 -> 1 | C6: =IF(_xlfn.IFNA(MATCH(D6,$D$1:D5,0),0)=0,MAX($C$1:C5)+1,"") -> 4 | D6: KLN-SPP2-AA-031 | E6: =_xlfn.NUMBERVALUE(RIGHT(D6,3)) -> 31 | F6: NAR TRANSPORT SERVICES MMC | G6: +994512449400 | H6: 📞 | I6: 💬 | J6: EB | K6: Active | L6: =IF(OR(K6="",N6=""),"",IF(L5="",MAX(L$2:L5),L5)+1) | M6: İbrahim Kemik | R6: Administration | S6: 031_Nar Transport_Services | U6: =HYPERLINK(subc_contr_folder_path&S6,"Open") -> Open | V6: =HYPERLINK(subc_contr_folder_path&S6&"\ipcs\"&Y6,"Open") -> #VALUE! | W6: =HYPERLINK(subc_contr_folder_path&S6&"\ipcs\"&Y6&"\"&"log.xlsx","Open") -> #VALUE! | X6: =HYPERLINK(subc_contr_folder_path&S6&"\ipcs\"&Y6&"\"&E6&"-"&Y6&".pdf","Open") -> #VALUE! | Y6: =IF(Z6="","",Z6) -> #VALUE! | Z6: #VALUE! | AC6: + | AD6: +
A7: =+A6+1 -> 6 | B7: =COUNTIF(INDIRECT("D1:D"&ROW()-1),D7)+1 -> 2 | C7: =IF(_xlfn.IFNA(MATCH(D7,$D$1:D6,0),0)=0,MAX($C$1:C6)+1,"") | D7: KLN-SPP2-AA-031 | E7: =_xlfn.NUMBERVALUE(RIGHT(D7,3)) -> 31 | F7: NAR TRANSPORT SERVICES MMC | J7: EB | K7: Active | L7: =IF(OR(K7="",N7=""),"",IF(L6="",MAX(L$2:L6),L6)+1) -> 2 | M7: Mustafa Yazıcı | N7: 90GG153 | O7: + | P7: Avtosəbət | Q7: ISUZU NPR66 | R7: Fit-out works | S7: 031_Nar Transport_Services | Y7: =IF(Z7="","",Z7) -> #VALUE! | Z7: #VALUE! | AC7: + | AD7: + | AE7: + | AF7: +
A8: =+A7+1 -> 7 | B8: =COUNTIF(INDIRECT("D1:D"&ROW()-1),D8)+1 -> 1 | C8: =IF(_xlfn.IFNA(MATCH(D8,$D$1:D7,0),0)=0,MAX($C$1:C7)+1,"") -> 5 | D8: KLN-SPP2-AA-033 | E8: =_xlfn.NUMBERVALUE(RIGHT(D8,3)) -> 33 | F8: AKKOL HAZIR YEMEK SAN. TIC. AS | G8: +994514299334 | H8: 📞 | I8: 💬 | J8: EB | K8: Active | L8: =IF(OR(K8="",N8=""),"",IF(L7="",MAX(L$2:L7),L7)+1) | M8: İbrahim Kemik | R8: Administration | S8: 033_Akkol Hazir Yemek | U8: =HYPERLINK(subc_contr_folder_path&S8,"Open") -> Open | V8: =HYPERLINK(subc_contr_folder_path&S8&"\ipcs\"&Y8,"Open") -> #VALUE! | W8: =HYPERLINK(subc_contr_folder_path&S8&"\ipcs\"&Y8&"\"&"log.pdf","Open") -> #VALUE! | X8: =HYPERLINK(subc_contr_folder_path&S8&"\ipcs\"&Y8&"\"&E8&"-"&Y8&".pdf","Open") -> #VALUE! | Y8: =IF(Z8="","",Z8) -> #VALUE! | Z8: #VALUE! | AC8: + | AD8: + | AE8: + | AF8: + | AG8: + | AH8: + | AI8: +
A9: =+A8+1 -> 8 | B9: =COUNTIF(INDIRECT("D1:D"&ROW()-1),D9)+1 -> 1 | C9: =IF(_xlfn.IFNA(MATCH(D9,$D$1:D8,0),0)=0,MAX($C$1:C8)+1,"") -> 6 | D9: KLN-SPP2-EQ-046 | E9: =_xlfn.NUMBERVALUE(RIGHT(D9,3)) -> 46 | F9: HARDCORE CE MMC | G9: +994703775515 | H9: 📞 | I9: 💬 | J9: EB | L9: =IF(OR(K9="",N9=""),"",IF(L8="",MAX(L$2:L8),L8)+1) | N9: 110FY523-D | P9: Roller | Q9: CAT CS 56B Vərdənə | R9: Earthworks | S9: 046_Hardcore Equipment | U9: =HYPERLINK(subc_contr_folder_path&S9,"Open") -> Open | V9: =HYPERLINK(subc_contr_folder_path&S9&"\ipcs","Open") -> Open | W9: =HYPERLINK(subc_contr_folder_path&S9&"\ipcs\"&Y9&"\"&"log.pdf","Open") -> #VALUE! | X9: =HYPERLINK(subc_contr_folder_path&S9&"\ipcs\"&Y9&"\"&E9&"-"&Y9&".pdf","Open") -> #VALUE! | Y9: =IF(Z9="","",Z9) -> #VALUE! | Z9: #VALUE!
A10: =+A9+1 -> 9 | B10: =COUNTIF(INDIRECT("D1:D"&ROW()-1),D10)+1 -> 2 | C10: =IF(_xlfn.IFNA(MATCH(D10,$D$1:D9,0),0)=0,MAX($C$1:C9)+1,"") | D10: KLN-SPP2-EQ-046 | E10: =_xlfn.NUMBERVALUE(RIGHT(D10,3)) -> 46 | F10: HARDCORE CE MMC | G10: +994703775515 | H10: 📞 | I10: 💬 | J10: EB | L10: =IF(OR(K10="",N10=""),"",IF(L9="",MAX(L$2:L9),L9)+1) | N10: 110FY524-N | P10: Roller | R10: Earthworks | S10: 046_Hardcore Equipment | Y10: =IF(Z10="","",Z10) -> #VALUE! | Z10: #VALUE!
A11: =+A10+1 -> 10 | B11: =COUNTIF(INDIRECT("D1:D"&ROW()-1),D11)+1 -> 3 | C11: =IF(_xlfn.IFNA(MATCH(D11,$D$1:D10,0),0)=0,MAX($C$1:C10)+1,"") | D11: KLN-SPP2-EQ-046 | E11: =_xlfn.NUMBERVALUE(RIGHT(D11,3)) -> 46 | F11: HARDCORE CE MMC | G11: +994703775515 | H11: 📞 | I11: 💬 | J11: EB | L11: =IF(OR(K11="",N11=""),"",IF(L10="",MAX(L$2:L10),L10)+1) | N11: 110FY523-N | P11: Roller | R11: Earthworks | S11: 046_Hardcore Equipment | Y11: =IF(Z11="","",Z11) -> #VALUE! | Z11: #VALUE!
A12: =+A11+1 -> 11 | B12: =COUNTIF(INDIRECT("D1:D"&ROW()-1),D12)+1 -> 4 | C12: =IF(_xlfn.IFNA(MATCH(D12,$D$1:D11,0),0)=0,MAX($C$1:C11)+1,"") | D12: KLN-SPP2-EQ-046 | E12: =_xlfn.NUMBERVALUE(RIGHT(D12,3)) -> 46 | F12: HARDCORE CE MMC | G12: +994703775515 | H12: 📞 | I12: 💬 | J12: EB | L12: =IF(OR(K12="",N12=""),"",IF(L11="",MAX(L$2:L11),L11)+1) | N12: 10AD801-N | P12: Excovator | R12: Earthworks | S12: 046_Hardcore Equipment | Y12: =IF(Z12="","",Z12) -> #VALUE! | Z12: #VALUE!
A13: =+A12+1 -> 12 | B13: =COUNTIF(INDIRECT("D1:D"&ROW()-1),D13)+1 -> 5 | C13: =IF(_xlfn.IFNA(MATCH(D13,$D$1:D12,0),0)=0,MAX($C$1:C12)+1,"") | D13: KLN-SPP2-EQ-046 | E13: =_xlfn.NUMBERVALUE(RIGHT(D13,3)) -> 46 | F13: HARDCORE CE MMC | G13: +994703775515 | H13: 📞 | I13: 💬 | J13: EB | L13: =IF(OR(K13="",N13=""),"",IF(L12="",MAX(L$2:L12),L12)+1) | N13: 10AD801-D | P13: Excavator | Q13: Hyundai R380LC-9SH | R13: Earthworks | S13: 046_Hardcore Equipment | Y13: =IF(Z13="","",Z13) -> #VALUE! | Z13: #VALUE!
A14: =+A13+1 -> 13 | B14: =COUNTIF(INDIRECT("D1:D"&ROW()-1),D14)+1 -> 6 | C14: =IF(_xlfn.IFNA(MATCH(D14,$D$1:D13,0),0)=0,MAX($C$1:C13)+1,"") | D14: KLN-SPP2-EQ-046 | E14: =_xlfn.NUMBERVALUE(RIGHT(D14,3)) -> 46 | F14: HARDCORE CE MMC | G14: +994703775515 | H14: 📞 | I14: 💬 | J14: EB | L14: =IF(OR(K14="",N14=""),"",IF(L13="",MAX(L$2:L13),L13)+1) | N14: 110FY524-D | P14: Roller | R14: Earthworks | S14: 046_Hardcore Equipment | Y14: =IF(Z14="","",Z14) -> #VALUE! | Z14: #VALUE!
A15: =+A14+1 -> 14 | B15: =COUNTIF(INDIRECT("D1:D"&ROW()-1),D15)+1 -> 7 | C15: =IF(_xlfn.IFNA(MATCH(D15,$D$1:D14,0),0)=0,MAX($C$1:C14)+1,"") | D15: KLN-SPP2-EQ-046 | E15: =_xlfn.NUMBERVALUE(RIGHT(D15,3)) -> 46 | F15: HARDCORE CE MMC | G15: +994703775515 | H15: 📞 | I15: 💬 | J15: EB | L15: =IF(OR(K15="",N15=""),"",IF(L14="",MAX(L$2:L14),L14)+1) | N15: 10AB468 | P15: Loader | S15: 046_Hardcore Equipment | Y15: =IF(Z15="","",Z15) -> #VALUE! | Z15: #VALUE!
A16: =+A15+1 -> 15 | B16: =COUNTIF(INDIRECT("D1:D"&ROW()-1),D16)+1 -> 1 | C16: =IF(_xlfn.IFNA(MATCH(D16,$D$1:D15,0),0)=0,MAX($C$1:C15)+1,"") -> 7 | D16: KLN-SPP2-EQ-050 | E16: =_xlfn.NUMBERVALUE(RIGHT(D16,3)) -> 50 | F16: LOFT CONSTRUCTION | G16: +994503774242 | H16: 📞 | I16: 💬 | J16: EB | K16: Active | L16: =IF(OR(K16="",N16=""),"",IF(L15="",MAX(L$2:L15),L15)+1) -> 3 | M16: Tolga Mutlu | N16: 61AB256 | P16: Qreyder | Q16: Luigong GLG 4215D | R16: Earthworks | S16: 050_Loft Construction | U16: =HYPERLINK(subc_contr_folder_path&S16,"Open") -> Open | V16: =HYPERLINK(subc_contr_folder_path&S16&"\ipcs\"&Y16,"Open") -> #VALUE! | W16: =HYPERLINK(subc_contr_folder_path&S16&"\ipcs\"&Y16&"\"&"log.pdf","Open") -> #VALUE! | X16: =HYPERLINK(subc_contr_folder_path&S16&"\ipcs\"&Y16&"\"&E16&"-"&Y16&".pdf","Open") -> #VALUE! | Y16: =IF(Z16="","",Z16) -> #VALUE! | Z16: #VALUE! | AC16: çıxış | AD16: + | AE16: + | AF16: + | AG16: + | AH16: + | AI16: + | AJ16: +
A17: =+A16+1 -> 16 | B17: =COUNTIF(INDIRECT("D1:D"&ROW()-1),D17)+1 -> 1 | C17: =IF(_xlfn.IFNA(MATCH(D17,$D$1:D16,0),0)=0,MAX($C$1:C16)+1,"") -> 8 | D17: KLN-SPP2-EQ-051 | E17: =_xlfn.NUMBERVALUE(RIGHT(D17,3)) -> 51 | F17: INTERMAK GROUP MMC | G17: +994102305309 | H17: 📞 | I17: 💬 | J17: EB | K17: Active | L17: =IF(OR(K17="",N17=""),"",IF(L16="",MAX(L$2:L16),L16)+1) -> 4 | M17: Mustafa Yazıcı | N17: 10AD071 | O17: + | P17: Telehandler | Q17: Manito 1740 | R17: Fit-out works | S17: 051_Intermak Group | U17: =HYPERLINK(subc_contr_folder_path&S17,"Open") -> Open | V17: =HYPERLINK(subc_contr_folder_path&S17&"\ipcs\"&Y17,"Open") -> #VALUE! | W17: =HYPERLINK(subc_contr_folder_path&S17&"\ipcs\"&Y17&"\"&"log.pdf","Open") -> #VALUE! | X17: =HYPERLINK(subc_contr_folder_path&S17&"\ipcs\"&Y17&"\"&E17&"-"&Y17&".pdf","Open") -> #VALUE! | Y17: =IF(Z17="","",Z17) -> #VALUE! | Z17: #VALUE! | AD17: + | AE17: + | AF17: + | AG17: + | AH17: + | AI17: + | AJ17: +
A18: =+A17+1 -> 17 | B18: =COUNTIF(INDIRECT("D1:D"&ROW()-1),D18)+1 -> 2 | C18: =IF(_xlfn.IFNA(MATCH(D18,$D$1:D17,0),0)=0,MAX($C$1:C17)+1,"") | D18: KLN-SPP2-EQ-051 | E18: =_xlfn.NUMBERVALUE(RIGHT(D18,3)) -> 51 | F18: INTERMAK GROUP MMC | G18: +994102305309 | H18: 📞 | I18: 💬 | J18: EB | L18: =IF(OR(K18="",N18=""),"",IF(L17="",MAX(L$2:L17),L17)+1) | N18: 10BA857 | P18: Telehandler | Q18: Manito 1740 | R18: Rough Works | S18: 051_Intermak Group | Y18: =IF(Z18="","",Z18) -> #VALUE! | Z18: #VALUE!
A19: =+A18+1 -> 18 | B19: =COUNTIF(INDIRECT("D1:D"&ROW()-1),D19)+1 -> 3 | C19: =IF(_xlfn.IFNA(MATCH(D19,$D$1:D18,0),0)=0,MAX($C$1:C18)+1,"") | D19: KLN-SPP2-EQ-051 | E19: =_xlfn.NUMBERVALUE(RIGHT(D19,3)) -> 51 | F19: INTERMAK GROUP MMC | G19: +994102305309 | H19: 📞 | I19: 💬 | J19: EB | L19: =IF(OR(K19="",N19=""),"",IF(L18="",MAX(L$2:L18),L18)+1) | N19: 10BA194 | S19: 051_Intermak Group | Y19: =IF(Z19="","",Z19) -> #VALUE! | Z19: #VALUE!
A20: =+A19+1 -> 19 | B20: =COUNTIF(INDIRECT("D1:D"&ROW()-1),D20)+1 -> 4 | C20: =IF(_xlfn.IFNA(MATCH(D20,$D$1:D19,0),0)=0,MAX($C$1:C19)+1,"") | D20: KLN-SPP2-EQ-051 | E20: =_xlfn.NUMBERVALUE(RIGHT(D20,3)) -> 51 | F20: INTERMAK GROUP MMC | G20: +994102305309 | H20: 📞 | I20: 💬 | J20: EB | L20: =IF(OR(K20="",N20=""),"",IF(L19="",MAX(L$2:L19),L19)+1) | N20: 10AD015 | P20: Mini loader | Q20: Bobcat S450 | R20: Earthworks | S20: 051_Intermak Group | Y20: =IF(Z20="","",Z20) -> #VALUE! | Z20: #VALUE!
A21: =+A20+1 -> 20 | B21: =COUNTIF(INDIRECT("D1:D"&ROW()-1),D21)+1 -> 5 | C21: =IF(_xlfn.IFNA(MATCH(D21,$D$1:D20,0),0)=0,MAX($C$1:C20)+1,"") | D21: KLN-SPP2-EQ-051 | E21: =_xlfn.NUMBERVALUE(RIGHT(D21,3)) -> 51 | F21: INTERMAK GROUP MMC | G21: +994102305309 | H21: 📞 | I21: 💬 | J21: EB | K21: Active | L21: =IF(OR(K21="",N21=""),"",IF(L20="",MAX(L$2:L20),L20)+1) -> 5 | M21: Mustafa Yazıcı | N21: XE120W | O21: + | P21: Qayçılı səbət | Q21: Mantall | R21: Fit-out works | S21: 051_Intermak Group | Z21: #VALUE! | AD21: + | AE21: + | AF21: + | AG21: +
A22: =+A21+1 -> 21 | B22: =COUNTIF(INDIRECT("D1:D"&ROW()-1),D22)+1 -> 6 | C22: =IF(_xlfn.IFNA(MATCH(D22,$D$1:D21,0),0)=0,MAX($C$1:C21)+1,"") | D22: KLN-SPP2-EQ-051 | E22: =_xlfn.NUMBERVALUE(RIGHT(D22,3)) -> 51 | F22: INTERMAK GROUP MMC | G22: +994102305309 | H22: 📞 | I22: 💬 | J22: EB | K22: Active | L22: =IF(OR(K22="",N22=""),"",IF(L21="",MAX(L$2:L21),L21)+1) -> 6 | M22: Mustafa Yazıcı | N22: XE160W | O22: + | P22: Qayçılı səbət | Q22: Mantall | R22: Fit-out works | S22: 051_Intermak Group | Z22: #VALUE! | AD22: + | AE22: + | AF22: + | AG22: +
A23: =+A22+1 -> 22 | B23: =COUNTIF(INDIRECT("D1:D"&ROW()-1),D23)+1 -> 7 | C23: =IF(_xlfn.IFNA(MATCH(D23,$D$1:D22,0),0)=0,MAX($C$1:C22)+1,"") | D23: KLN-SPP2-EQ-051 | E23: =_xlfn.NUMBERVALUE(RIGHT(D23,3)) -> 51 | F23: INTERMAK GROUP MMC | G23: +994102305309 | H23: 📞 | I23: 💬 | J23: EB | K23: Active | L23: =IF(OR(K23="",N23=""),"",IF(L22="",MAX(L$2:L22),L22)+1) -> 7 | M23: Mustafa Yazıcı | N23: CEPT1212 | O23: + | P23: Qayçılı səbət | Q23: Mantall | R23: Fit-out works | S23: 051_Intermak Group | Z23: #VALUE! | AD23: + | AE23: + | AF23: + | AG23: +
A24: =+A23+1 -> 23 | B24: =COUNTIF(INDIRECT("D1:D"&ROW()-1),D24)+1 -> 1 | C24: =IF(_xlfn.IFNA(MATCH(D24,$D$1:D23,0),0)=0,MAX($C$1:C23)+1,"") -> 9 | D24: KLN-SPP2-EQ-052 | E24: =_xlfn.NUMBERVALUE(RIGHT(D24,3)) -> 52 | F24: DTS MMC | J24: EB | L24: =IF(OR(K24="",N24=""),"",IF(L23="",MAX(L$2:L23),L23)+1) | N24: 10AC750 | S24: 052_DTS | U24: =HYPERLINK(subc_contr_folder_path&S24,"Open") -> Open | V24: =HYPERLINK(subc_contr_folder_path&S24&"\ipcs","Open") -> Open | W24: =HYPERLINK(subc_contr_folder_path&S24&"\ipcs\"&Y24&"\"&"log.pdf","Open") -> #VALUE! | X24: =HYPERLINK(subc_contr_folder_path&S24&"\ipcs\"&Y24&"\"&E24&"-"&Y24&".pdf","Open") -> #VALUE! | Y24: =IF(Z24="","",Z24) -> #VALUE! | Z24: #VALUE!
A25: =+A24+1 -> 24 | B25: =COUNTIF(INDIRECT("D1:D"&ROW()-1),D25)+1 -> 2 | C25: =IF(_xlfn.IFNA(MATCH(D25,$D$1:D24,0),0)=0,MAX($C$1:C24)+1,"") | D25: KLN-SPP2-EQ-052 | E25: =_xlfn.NUMBERVALUE(RIGHT(D25,3)) -> 52 | F25: DTS MMC | J25: EB | L25: =IF(OR(K25="",N25=""),"",IF(L24="",MAX(L$2:L24),L24)+1) | N25: 10BC326 | S25: 052_DTS | Y25: =IF(Z25="","",Z25) -> #VALUE! | Z25: #VALUE!
A26: =+A25+1 -> 25 | B26: =COUNTIF(INDIRECT("D1:D"&ROW()-1),D26)+1 -> 1 | C26: =IF(_xlfn.IFNA(MATCH(D26,$D$1:D25,0),0)=0,MAX($C$1:C25)+1,"") -> 10 | D26: KLN-SPP2-EQ-065 | E26: =_xlfn.NUMBERVALUE(RIGHT(D26,3)) -> 65 | F26: ETIBAR MAMMADOV | G26: +994555923919 | H26: 📞 | I26: 💬 | J26: EB | K26: Active | L26: =IF(OR(K26="",N26=""),"",IF(L25="",MAX(L$2:L25),L25)+1) -> 8 | M26: Tolga Mutlu | N26: 01BA176 | P26: Excavator | Q26: Doosan DH55-V | R26: Earthworks | S26: 065_Etibar Mammadov | U26: =HYPERLINK(subc_contr_folder_path&S26,"Open") -> Open | V26: =HYPERLINK(subc_contr_folder_path&S26&"\ipcs\"&Y26,"Open") -> #VALUE! | W26: =HYPERLINK(subc_contr_folder_path&S26&"\ipcs\"&Y26&"\"&"log.pdf","Open") -> #VALUE! | X26: =HYPERLINK(subc_contr_folder_path&S26&"\ipcs\"&Y26&"\"&E26&"-"&Y26&".pdf","Open") -> #VALUE! | Y26: =IF(Z26="","",Z26) -> #VALUE! | Z26: #VALUE! | AD26: + | AE26: + | AF26: + | AG26: + | AH26: + | AI26: + | AJ26: +
A27: =+A26+1 -> 26 | B27: =COUNTIF(INDIRECT("D1:D"&ROW()-1),D27)+1 -> 2 | C27: =IF(_xlfn.IFNA(MATCH(D27,$D$1:D26,0),0)=0,MAX($C$1:C26)+1,"") | D27: KLN-SPP2-EQ-065 | E27: =_xlfn.NUMBERVALUE(RIGHT(D27,3)) -> 65 | F27: ETIBAR MAMMADOV | G27: +994555923919 | H27: 📞 | I27: 💬 | J27: EB | L27: =IF(OR(K27="",N27=""),"",IF(L26="",MAX(L$2:L26),L26)+1) | N27: 10BD252 | P27: Loader | Q27: Liugong CLG 375A | R27: Earthworks | S27: 065_Etibar Mammadov | Y27: =IF(Z27="","",Z27) -> #VALUE! | Z27: #VALUE!
A28: =+A27+1 -> 27 | B28: =COUNTIF(INDIRECT("D1:D"&ROW()-1),D28)+1 -> 1 | C28: =IF(_xlfn.IFNA(MATCH(D28,$D$1:D27,0),0)=0,MAX($C$1:C27)+1,"") -> 11 | D28: KLN-SPP2-EQ-085 | E28: =_xlfn.NUMBERVALUE(RIGHT(D28,3)) -> 85 | F28: BABEK ALBANDOV | G28: +994773389192 | H28: 📞 | I28: 💬 | J28: EB | K28: Active | L28: =IF(OR(K28="",N28=""),"",IF(L27="",MAX(L$2:L27),L27)+1) -> 9 | M28: Cəsur | N28: 77SN951 | P28: Mobil beton nasosu | Q28: Mercedes-Benz Actros 3341 Putzmeister 38 | R28: Rough Works | S28: 085_Babek Albandov | U28: =HYPERLINK(subc_contr_folder_path&S28,"Open") -> Open | V28: =HYPERLINK(subc_contr_folder_path&S28&"\ipcs\"&Y28,"Open") -> #VALUE! | W28: =HYPERLINK(subc_contr_folder_path&S28&"\ipcs\"&Y28&"\"&"log.pdf","Open") -> #VALUE! | X28: =HYPERLINK(subc_contr_folder_path&S28&"\ipcs\"&Y28&"\"&E28&"-"&Y28&".pdf","Open") -> #VALUE! | Y28: =IF(Z28="","",Z28) -> #VALUE! | Z28: #VALUE! | AC28: çıxış | AD28: + | AE28: + | AF28: + | AG28: + | AH28: + | AI28: + | AJ28: +
A29: =+A28+1 -> 28 | B29: =COUNTIF(INDIRECT("D1:D"&ROW()-1),D29)+1 -> 1 | C29: =IF(_xlfn.IFNA(MATCH(D29,$D$1:D28,0),0)=0,MAX($C$1:C28)+1,"") -> 12 | D29: KLN-SPP2-EQ-091 | E29: =_xlfn.NUMBERVALUE(RIGHT(D29,3)) -> 91 | F29: ELSAD QULIYEV | G29: +994515992662 | H29: 📞 | I29: 💬 | J29: EB | K29: Active | L29: =IF(OR(K29="",N29=""),"",IF(L28="",MAX(L$2:L28),L28)+1) -> 10 | M29: - | N29: 90VJ454 | P29: Su tankeri | Q29: Kamaz 53-12 Ş-DƏ ATS-3613 | R29: Warehouse | S29: 091_Quliyev Elşad Ramis | U29: =HYPERLINK(subc_contr_folder_path&S29,"Open") -> Open | V29: =HYPERLINK(subc_contr_folder_path&S29&"\ipcs\"&Y29,"Open") -> #VALUE! | W29: =HYPERLINK(subc_contr_folder_path&S29&"\ipcs\"&Y29&"\"&"log.pdf","Open") -> #VALUE! | X29: =HYPERLINK(subc_contr_folder_path&S29&"\ipcs\"&Y29&"\"&E29&"-"&Y29&".pdf","Open") -> #VALUE! | Y29: =IF(Z29="","",Z29) -> #VALUE! | Z29: #VALUE! | AD29: + | AE29: + | AF29: + | AG29: + | AH29: + | AI29: + | AJ29: +
A30: =+A29+1 -> 29 | B30: =COUNTIF(INDIRECT("D1:D"&ROW()-1),D30)+1 -> 1 | C30: =IF(_xlfn.IFNA(MATCH(D30,$D$1:D29,0),0)=0,MAX($C$1:C29)+1,"") -> 13 | D30: KLN-SPP2-EQ-094 | E30: =_xlfn.NUMBERVALUE(RIGHT(D30,3)) -> 94 | F30: XANIM ABDULLAYEVA | G30: +994517928522 | H30: 📞 | I30: 💬 | J30: EB | L30: =IF(OR(K30="",N30=""),"",IF(L29="",MAX(L$2:L29),L29)+1) | N30: 01BT754 | R30: HSE | S30: 094_Abdullayeva Xanım (Rasim) | U30: =HYPERLINK(subc_contr_folder_path&S30,"Open") -> Open | V30: =HYPERLINK(subc_contr_folder_path&S30&"\ipcs","Open") -> Open | W30: =HYPERLINK(subc_contr_folder_path&S30&"\ipcs\"&Y30&"\"&"log.pdf","Open") -> #VALUE! | X30: =HYPERLINK(subc_contr_folder_path&S30&"\ipcs\"&Y30&"\"&E30&"-"&Y30&".pdf","Open") -> #VALUE! | Y30: =IF(Z30="","",Z30) -> #VALUE! | Z30: #VALUE!
A31: =+A30+1 -> 30 | B31: =COUNTIF(INDIRECT("D1:D"&ROW()-1),D31)+1 -> 2 | C31: =IF(_xlfn.IFNA(MATCH(D31,$D$1:D30,0),0)=0,MAX($C$1:C30)+1,"") | D31: KLN-SPP2-EQ-094 | E31: =_xlfn.NUMBERVALUE(RIGHT(D31,3)) -> 94 | F31: XANIM ABDULLAYEVA | G31: +994517928522 | H31: 📞 | I31: 💬 | J31: EB | L31: =IF(OR(K31="",N31=""),"",IF(L30="",MAX(L$2:L30),L30)+1) | N31: 54BM823 | R31: HSE | S31: 094_Abdullayeva Xanım (Rasim) | Y31: =IF(Z31="","",Z31) -> #VALUE! | Z31: #VALUE!
A32: =+A31+1 -> 31 | B32: =COUNTIF(INDIRECT("D1:D"&ROW()-1),D32)+1 -> 1 | C32: =IF(_xlfn.IFNA(MATCH(D32,$D$1:D31,0),0)=0,MAX($C$1:C31)+1,"") -> 14 | D32: KLN-SPP2-EQ-095 | E32: =_xlfn.NUMBERVALUE(RIGHT(D32,3)) -> 95 | F32: IBRAHIM XALILOV | G32: +994502324211 | H32: 📞 | I32: 💬 | J32: EB | K32: Active | L32: =IF(OR(K32="",N32=""),"",IF(L31="",MAX(L$2:L31),L31)+1) -> 11 | M32: Tolga Mutlu | N32: 54BA209 | P32: Ekskavator | Q32: Hidromek HMK 200W-2 | R32: Earthworks | S32: 095_Xəlilov İbrahim | U32: =HYPERLINK(subc_contr_folder_path&S32,"Open") -> Open | V32: =HYPERLINK(subc_contr_folder_path&S32&"\ipcs\"&Y32,"Open") -> #VALUE! | W32: =HYPERLINK(subc_contr_folder_path&S32&"\ipcs\"&Y32&"\"&"log.pdf","Open") -> #VALUE! | X32: =HYPERLINK(subc_contr_folder_path&S32&"\ipcs\"&Y32&"\"&E32&"-"&Y32&".pdf","Open") -> #VALUE! | Y32: =IF(Z32="","",Z32) -> #VALUE! | Z32: #VALUE! | AD32: + | AE32: + | AF32: + | AG32: + | AH32: + | AI32: + | AJ32: +
A33: =+A32+1 -> 32 | B33: =COUNTIF(INDIRECT("D1:D"&ROW()-1),D33)+1 -> 1 | C33: =IF(_xlfn.IFNA(MATCH(D33,$D$1:D32,0),0)=0,MAX($C$1:C32)+1,"") -> 15 | D33: KLN-SPP2-EQ-098 | E33: =_xlfn.NUMBERVALUE(RIGHT(D33,3)) -> 98 | F33: HACIAGA KERIMOV | G33: +994503466032 | H33: 📞 | I33: 💬 | J33: EB | K33: Active | L33: =IF(OR(K33="",N33=""),"",IF(L32="",MAX(L$2:L32),L32)+1) -> 12 | M33: Mustafa Yazıcı | N33: 50BD416 | O33: + | P33: Dartıcı | Q33: KAMAZ 5410 | R33: Rough works | S33: 098_Kərimov Hacıağa | U33: =HYPERLINK(subc_contr_folder_path&S33,"Open") -> Open | V33: =HYPERLINK(subc_contr_folder_path&S33&"\ipcs\"&Y33,"Open") -> #VALUE! | W33: =HYPERLINK(subc_contr_folder_path&S33&"\ipcs\"&Y33&"\"&"log.pdf","Open") -> #VALUE! | X33: =HYPERLINK(subc_contr_folder_path&S33&"\ipcs\"&Y33&"\"&E33&"-"&Y33&".pdf","Open") -> #VALUE! | Y33: =IF(Z33="","",Z33) -> #VALUE! | Z33: #VALUE! | AD33: + | AE33: + | AF33: + | AG33: + | AH33: + | AI33: + | AJ33: +
A34: =+A33+1 -> 33 | B34: =COUNTIF(INDIRECT("D1:D"&ROW()-1),D34)+1 -> 1 | C34: =IF(_xlfn.IFNA(MATCH(D34,$D$1:D33,0),0)=0,MAX($C$1:C33)+1,"") -> 16 | D34: KLN-SPP2-EQ-099 | E34: =_xlfn.NUMBERVALUE(RIGHT(D34,3)) -> 99 | F34: YUSIF MAHARRAMOV | G34: +994559997804 | H34: 📞 | I34: 💬 | J34: EB | L34: =IF(OR(K34="",N34=""),"",IF(L33="",MAX(L$2:L33),L33)+1) | N34: 50BX301 | R34: HSE | S34: 099_Maharramov Yusif Qurban oğlu | U34: =HYPERLINK(subc_contr_folder_path&S34,"Open") -> Open | V34: =HYPERLINK(subc_contr_folder_path&S34&"\ipcs","Open") -> Open | W34: =HYPERLINK(subc_contr_folder_path&S34&"\ipcs\"&Y34&"\"&"log.pdf","Open") -> #VALUE! | X34: =HYPERLINK(subc_contr_folder_path&S34&"\ipcs\"&Y34&"\"&E34&"-"&Y34&".pdf","Open") -> #VALUE! | Y34: =IF(Z34="","",Z34) -> #VALUE! | Z34: #VALUE!
A35: =+A34+1 -> 34 | B35: =COUNTIF(INDIRECT("D1:D"&ROW()-1),D35)+1 -> 1 | C35: =IF(_xlfn.IFNA(MATCH(D35,$D$1:D34,0),0)=0,MAX($C$1:C34)+1,"") -> 17 | D35: KLN-SPP2-EQ-100 | E35: =_xlfn.NUMBERVALUE(RIGHT(D35,3)) -> 100 | F35: RUSLAN HUSEYNOV | G35: +994552212085 | H35: 📞 | I35: 💬 | J35: EB | K35: Active | L35: =IF(OR(K35="",N35=""),"",IF(L34="",MAX(L$2:L34),L34)+1) -> 13 | M35: Tolga Mutlu | N35: 22AB273 | P35: Excavator | Q35: Hitachi ZX48U-3 | R35: Earthworks | S35: 100_Hüseyinov Ruslan | U35: =HYPERLINK(subc_contr_folder_path&S35,"Open") -> Open | V35: =HYPERLINK(subc_contr_folder_path&S35&"\ipcs\"&Y35,"Open") -> #VALUE! | W35: =HYPERLINK(subc_contr_folder_path&S35&"\ipcs\"&Y35&"\"&"log.pdf","Open") -> #VALUE! | X35: =HYPERLINK(subc_contr_folder_path&S35&"\ipcs\"&Y35&"\"&E35&"-"&Y35&".pdf","Open") -> #VALUE! | Y35: =IF(Z35="","",Z35) -> #VALUE! | Z35: #VALUE! | AD35: + | AE35: + | AF35: + | AG35: + | AH35: + | AI35: + | AJ35: +
A36: =+A35+1 -> 35 | B36: =COUNTIF(INDIRECT("D1:D"&ROW()-1),D36)+1 -> 2 | C36: =IF(_xlfn.IFNA(MATCH(D36,$D$1:D35,0),0)=0,MAX($C$1:C35)+1,"") | D36: KLN-SPP2-EQ-100 | E36: =_xlfn.NUMBERVALUE(RIGHT(D36,3)) -> 100 | F36: RUSLAN HUSEYINOV | G36: +994552212085 | H36: 📞 | I36: 💬 | J36: EB | K36: Active | L36: =IF(OR(K36="",N36=""),"",IF(L35="",MAX(L$2:L35),L35)+1) -> 14 | M36: Tolga Mutlu | N36: 22AB283 | P36: Excavator | Q36: AUSA MH 15 | R36: Earthworks | S36: 100_Hüseyinov Ruslan | Z36: #VALUE! | AD36: + | AE36: + | AF36: + | AG36: +
A37: =+A36+1 -> 36 | B37: =COUNTIF(INDIRECT("D1:D"&ROW()-1),D37)+1 -> 1 | C37: =IF(_xlfn.IFNA(MATCH(D37,$D$1:D36,0),0)=0,MAX($C$1:C36)+1,"") -> 18 | D37: KLN-SPP2-EQ-102 | E37: =_xlfn.NUMBERVALUE(RIGHT(D37,3)) -> 102 | F37: KONUL HUSEYNOVA | G37: +994517928522 | H37: 📞 | I37: 💬 | J37: EB | K37: Active | L37: =IF(OR(K37="",N37=""),"",IF(L36="",MAX(L$2:L36),L36)+1) -> 15 | M37: Azər Əbilov | N37: 10MF640 | P37: Su tankeri | Q37: KAMAZ 55111 | R37: Rough Works | S37: 102_Huseynova Konul | U37: =HYPERLINK(subc_contr_folder_path&S37,"Open") -> Open | V37: =HYPERLINK(subc_contr_folder_path&S37&"\ipcs\"&Y37,"Open") -> #VALUE! | W37: =HYPERLINK(subc_contr_folder_path&S37&"\ipcs\"&Y37&"\"&"log.pdf","Open") -> #VALUE! | X37: =HYPERLINK(subc_contr_folder_path&S37&"\ipcs\"&Y37&"\"&E37&"-"&Y37&".pdf","Open") -> #VALUE! | Y37: =IF(Z37="","",Z37) -> #VALUE! | Z37: #VALUE! | AC37: + | AD37: + | AE37: + | AF37: + | AG37: + | AH37: + | AI37: +
A38: =+A37+1 -> 37 | B38: =COUNTIF(INDIRECT("D1:D"&ROW()-1),D38)+1 -> 2 | C38: =IF(_xlfn.IFNA(MATCH(D38,$D$1:D37,0),0)=0,MAX($C$1:C37)+1,"") | D38: KLN-SPP2-EQ-102 | E38: =_xlfn.NUMBERVALUE(RIGHT(D38,3)) -> 102 | F38: KONUL HUSEYNOVA | G38: +994517928522 | H38: 📞 | I38: 💬 | J38: EB | L38: =IF(OR(K38="",N38=""),"",IF(L37="",MAX(L$2:L37),L37)+1) | N38: 99HQ687 | R38: HSE | S38: 102_Huseynova Konul | Y38: =IF(Z38="","",Z38) -> #VALUE! | Z38: #VALUE!
A39: =+A38+1 -> 38 | B39: =COUNTIF(INDIRECT("D1:D"&ROW()-1),D39)+1 -> 3 | C39: =IF(_xlfn.IFNA(MATCH(D39,$D$1:D38,0),0)=0,MAX($C$1:C38)+1,"") | D39: KLN-SPP2-EQ-102 | E39: =_xlfn.NUMBERVALUE(RIGHT(D39,3)) -> 102 | F39: KONUL HUSEYNOVA | G39: +994517928522 | H39: 📞 | I39: 💬 | J39: EB | K39: Active | L39: =IF(OR(K39="",N39=""),"",IF(L38="",MAX(L$2:L38),L38)+1) -> 16 | M39: Tuncay Aktaş | N39: 54BM823 | P39: Su tankeri | Q39: KAMAZ | R39: HSE | S39: 102_Huseynova Konul | Z39: #VALUE! | AD39: + | AE39: + | AF39: + | AG39: +
A40: =+A39+1 -> 39 | B40: =COUNTIF(INDIRECT("D1:D"&ROW()-1),D40)+1 -> 4 | C40: =IF(_xlfn.IFNA(MATCH(D40,$D$1:D39,0),0)=0,MAX($C$1:C39)+1,"") | D40: KLN-SPP2-EQ-102 | E40: =_xlfn.NUMBERVALUE(RIGHT(D40,3)) -> 102 | F40: KONUL HUSEYNOVA | G40: +994517928522 | H40: 📞 | I40: 💬 | J40: EB | K40: Active | L40: =IF(OR(K40="",N40=""),"",IF(L39="",MAX(L$2:L39),L39)+1) -> 17 | M40: Tuncay Aktaş | N40: 01BT754 | P40: Su tankeri | Q40: KAMAZ | R40: HSE | S40: 102_Huseynova Konul | Z40: #VALUE! | AD40: + | AE40: + | AF40: + | AG40: +
...

Sheet vehicle-record
C1: ="KİRALIK ARAÇ GÜNLÜK PUANTAJ TAKİP FORMU - "&RIGHT(I4,3)&" - "&_xlfn.XLOOKUP(I4,data!D:D,data!Z:Z,,0)+M4 -> #VALUE!
L2: Record no | M2: Month | N2: Year | O2: Department | T2: Department | U2: Vəzifəsi | V2: ADI
A3: Araç Sahibi | C3: =_xlfn.XLOOKUP(L3,data!L:L,data!F:F,,0) -> NAR KRAN MMC | G3: Uygulama AYI | I3: =VLOOKUP(M3,Z3:AB14,2,0)&" "&N3 -> APREL 2026 | L3: 31 | M3: 4 | N3: 2026 | O3: =_xlfn.XLOOKUP(L3,data!L:L,data!R:R,0) -> Warehouse | T3: QA/QC | U3: Kalite Kontrok Şefi | V3: Hakan Alkan | Z3: 1 | AA3: =UPPER(AB3) -> YANVAR | AB3: yanvar
A4: Plakası | C4: {=INDEX(_xlfn.TEXTSPLIT(_xlfn.XLOOKUP(L3,data!L:L,data!N:N,,0),"-"),1)} -> 99DX853 | G4: Kontrat no | I4: =_xlfn.XLOOKUP(L3,data!L:L,data!D:D,,0) -> KLN-SPP2-EQ-119 | L4: 179 | M4: 2 | T4: Workshop | U4: Atölye şefi | V4: Mesut Fırat | Z4: 2 | AA4: =UPPER(AB4) -> FEVRAL | AB4: fevral
A5: Markası/Modeli | C5: =_xlfn.XLOOKUP(L3,data!L:L,data!Q:Q,,0) -> 0 | G5: IPC № | I5: =_xlfn.XLOOKUP(I4,data!D:D,data!Z:Z,,0)+M4 -> #VALUE! | T5: Administration | U5: İdari işler müdürü | V5: Ibrahim Kemik | Z5: 3 | AA5: =UPPER(AB5) -> MART | AB5: mart
A6: Növbə | C6: =IF(RIGHT(_xlfn.XLOOKUP(L3,data!L:L,data!N:N,,0))="N","GECƏ","") | G6: Tel | I6: =""&MID(_xlfn.XLOOKUP(L3,data!L:L,data!G:G,,0),2,12) -> 994502712731 | O6: {=_xlfn._xlws.FILTER(_xlfn._TRO_TRAILING(data!L:L),IFERROR(_xlfn.NUMBERVALUE(RIGHT(_xlfn._TRO_TRAILING(data!D:D),3)),"")=L4)} -> 23 | T6: Vinç sepet | U6: Vinç/Sepet sorumlusu | V6: Mustafa Yazıcı | Z6: 4 | AA6: =UPPER(AB6) -> APREL | AB6: aprel
A7: Gün | B7: Km Başı | C7: Km Sonu | D7: Sarf km | E7: Baş. Saati | F7: Bitiş Saati | G7: ƏLAVƏ İŞ / SAAT | H7: Yakıt | I7: İmza | J7: Notlar | T7: Earthworks | U7: Toprak işleri şefi | V7: Barış Gültekin | Z7: 5 | AA7: =UPPER(AB7) -> MAY | AB7: may
A8: 1 | L8: {=_xlfn.LET(_xlpm.days,A8:A38,IF(_xlpm.days="","",WEEKDAY(DATE(N3,M3,_xlpm.days))))} -> 4 | M8: =_xlfn.XLOOKUP(I4,data!D:D,data!Z:Z,,0) -> #VALUE! | T8: Rough Works | U8: Kaba işler şefi | V8: Ertuğ Kuban | Z8: 6 | AA8: =UPPER(AB8) -> IYUN | AB8: iyun
A9: =+A8+1 -> 2 | L9: 5 | T9: Warehouse | U9: Ambar şefi | V9: Ibrahim Akgün | Z9: 7 | AA9: =UPPER(AB9) -> IYUL | AB9: iyul
A10: =A9+1 -> 3 | L10: 6 | T10: HSE | U10: İSG Şefi | V10: Dilaver Türk | Z10: 8 | AA10: =UPPER(AB10) -> AVQUST | AB10: avqust
A11: =A10+1 -> 4 | L11: 7 | T11: Infrastructure | U11: Alt yapı ve Harita şefi | V11: Nurettin Biçer | Z11: 9 | AA11: =UPPER(AB11) -> SENTYABR | AB11: sentyabr
A12: =A11+1 -> 5 | L12: 1 | T12: Electrical | U12: Elektrik Department | V12: Burak Papila | Z12: 10 | AA12: =UPPER(AB12) -> OKTYABR | AB12: oktyabr
A13: =A12+1 -> 6 | L13: 2 | T13: Fit-out works | U13: İnce işler şefi | V13: İrfan Karakaya | Z13: 11 | AA13: =UPPER(AB13) -> NOYABR | AB13: noyabr
A14: =A13+1 -> 7 | L14: 3 | Z14: 12 | AA14: =UPPER(AB14) -> DEKABR | AB14: dekabr
A15: =A14+1 -> 8 | L15: 4
A16: =A15+1 -> 9 | L16: 5
A17: =A16+1 -> 10 | L17: 6
A18: =A17+1 -> 11 | L18: 7
A19: =A18+1 -> 12 | L19: 1
A20: =A19+1 -> 13 | L20: 2
A21: =A20+1 -> 14 | L21: 3
A22: =A21+1 -> 15 | L22: 4
A23: =A22+1 -> 16 | L23: 5
A24: =A23+1 -> 17 | L24: 6
A25: =A24+1 -> 18 | L25: 7
A26: =A25+1 -> 19 | L26: 1
... A35: =A34+1 -> 28 | L35: 3
A36: =IF(DAY(EOMONTH(DATE($N$3,$M$3,1),0))<ROW()-7,"",A35+1) -> 29 | L36: 4
A37: =IF(DAY(EOMONTH(DATE($N$3,$M$3,1),0))<ROW()-7,"",A36+1) -> 30 | L37: 5
A38: =IF(DAY(EOMONTH(DATE($N$3,$M$3,1),0))<ROW()-7,"",A37+1)
B39: CƏMİ TƏK: | C39: =+COUNTA(C8:C38) -> 0 | D39: CƏMİ CÜT: | E39: =+COUNTA(E8:E38) -> 0 | F39: CƏM SAAT: | G39: =SUM(G8:G38) -> 0 | H39: =SUM(H8:H38) -> 0
A40: TƏRƏFLƏR | D40: VƏZİFƏ | G40: ADI | J40: İMZA
A41: =_xlfn.XLOOKUP(L3,data!L:L,data!F:F) -> NAR KRAN MMC | D41: Taşefon sorumlusu | G41: =A41 -> NAR KRAN MMC
A42: Kolin İnşaat | D42: Yetkili formen | G42: =_xlfn.XLOOKUP(L3,data!L:L,data!M:M) -> Mustafa Yazıcı
A43: Kolin İnşaat | D43: =VLOOKUP(O3,_xlfn._TRO_TRAILING(T:V),2,0) -> Ambar şefi | G43: =VLOOKUP(O3,_xlfn._TRO_TRAILING(T:V),3,0) -> Ibrahim Akgün
A44: DİQQƏT!!! TOPLAM GÜN VƏ ƏLAVƏ SAAT MİQDARI MÜTLƏQ QEYD EDİLMƏLİDİR

Sheet notes
A1: Notes
B2: Kəsinti notlarının detallarını yaz

Sheet config
A1: Subcontractor contracts folder path | B1: \\DATA\DataServer\Teknik Ofis\00_SPP2 Taseron Sozlesmeleri\
A3: Cell name | B3: Position | C3: Name Surname
A4: Technical Office Cheif | B4: Technical Office Cheif Texniki Şöbə Şefi | C4: Mehmet Özgün DEDEKARGINOĞLU
A5: Site Manager | B5: Site Manager Sahə Rəhbəri | C5: Turgut BAL
