Workbook
Name contract_no: view__cover!$R$1
Name contract_nos: _xlfn.DROP(log_contracts!$B:$B,1)
Name ipc_date_end: view__cover!$L$5
Name ipc_date_start: view__cover!$L$4
Name ipc_no: view__cover!$R$2

Sheet view__cover
A1: #VALUE! | C1: Kolin Construction, Tourism, Industry and Trading Co. Inc. Kolin İnşaat, Turizm, Sənaye və Ticarət Co. Inc. | J1: Contract No | K1: ="KLN-SPP2-"&_xlfn.XLOOKUP(R1,log_contracts!B:B,log_contracts!C:C)&"-"&TEXT(R1,"000") -> KLN-SPP2-AA-031 | N1: Contract no: | O1: 31 | R1: =IF(O1="",_xlfn.XLOOKUP(P2,log_ipcs!A:A,log_ipcs!C:C,,0),O1) -> 31 | U1: ATTENTION!!!➡️➡️ | V1: =HYPERLINK("\\DATA\DataServer\Teknik Ofis\00_SPP2 Taseron Sozlesmeleri\000_FOLLOW-UP\S2 Subcon IPC Log.xlsx","Open IPC Log to Fix #REF error") -> Open IPC Log to Fix #REF error
J2: IPC No | K2: =R2 -> 14 | N2: IPC no | O2: =IF(Q2="",MAX(_xlfn.ANCHORARRAY(S2)),Q2) -> 14 | P2: 129 | R2: =IF(O2="",_xlfn.XLOOKUP(P2,log_ipcs!A:A,log_ipcs!D:D,,0),O2) -> 14 | S2: {=_xlfn._xlws.FILTER(log_ipcs!D:D,log_ipcs!C:C=contract_no)} -> 1 | U2: 1 | V2: =HYPERLINK("\\DATA\DataServer\Teknik Ofis\00_SPP2 Taseron Sozlesmeleri\"&_xlfn.XLOOKUP(O1,log_contracts!B:B,log_contracts!I:I,,0)&"\ipcs\"&IF(U2="",O2,U2)&"\"&O1&"-"&IF(U2="",O2,U2)&".pdf","Open"&" "&O1&"-"&IF(U2="",O2,U2)&" PDF") -> Open 31-1 PDF
A3: Interim Payment Certificate (IPC) Müvəqqəti Ödəniş Şəhadətnaməsi | S3: 2 | U3: =_xlfn.MAXIFS(INDIRECT("'[S2 Subcon IPC Log.xlsx]Subcon IPC Log'!"&"D:D"),INDIRECT("'[S2 Subcon IPC Log.xlsx]Subcon IPC Log'!"&"C:C"),K1)=MAX(_xlfn.ANCHORARRAY(S2)) -> #REF!
A4: Project : Layihə: | C4: Construction of the facilities and buildings, storages, and other structures, including roads and all industrial utilities for establishment of “Sitalchay 2” Production Plant | J4: Invoice Period (Start): Faktura müddəti (başlanğıc): | L4: =VLOOKUP(TEXT(O1,"000")&"-"&TEXT(O2,"000"),log_ipcs!B:F,4,0) -> 46082 | N4: =IF(L6>L4,"ERROR","") | S4: 3
J5: Invoice Period (Finish): Faktura müddəti (Son): | L5: {=EOMONTH(MAX(_xlfn.LET(_xlpm.ym,_xlfn._xlws.FILTER(quantities!B:C,(quantities!D:D=contract_no)*(quantities!E:E=ipc_no)),DATE(INDEX(_xlpm.ym,,1),INDEX(_xlpm.ym,,2),1))),0)} -> 46112 | S5: 4
A6: Subcontractor: Subpodratçı: | C6: =_xlfn.XLOOKUP(R1,log_contracts!B:B,log_contracts!E:E,,0) -> NAR TRANSPORT SERVICES MMC | J6: Commencement Date: Başlanğıc tarixi: | L6: {=_xlfn.XLOOKUP(R1,_xlfn._TRO_TRAILING(log_contracts!B:B),_xlfn._TRO_TRAILING(log_contracts!H:H),,0)} -> 45693 | S6: 5
J7: Completion Date: Bitmə tarixi: | S7: 6
A8: Scope of Work: İşin həcmi: | C8: =_xlfn.XLOOKUP(R1,log_contracts!B:B,log_contracts!F:F,,0) -> Rental Vehicle Kiralıq Vasitə | J8: Contract Type (Subc.): Müqavilənin növü (Subp.): | L8: Unit Price Vahidin qiyməti | S8: 7
J9: Contract Value: Müqavilənin dəyəri: | S9: 8
A10: Payment Table Ödəniş cədvəli | S10: 9
S11: 10
A12: A | B12: ="Cumulative Value Of The Works Executed as of " & TEXT(L5," DD/MMM/YYYY") &CHAR(10)&TEXT(L5,"DD/MMM/YYYY") & "cu il tarixindən etibarən görülmüş işlərin ümumi dəyəri:" -> Cumulative Value Of The Works Executed as of 31/Mar/2026 31/Mar/2026cu il tarixindən etibarən görülmüş işlərin ümumi dəyəri: | J12: =view_calc!I165 -> 734672 | M12: =SUMIFS( INDIRECT("'[S2 Subcon IPC Log.xlsx]Subcon IPC Log'!"&"$O:$O"), INDIRECT("'[S2 Subcon IPC Log.xlsx]Subcon IPC Log'!"&"$C:$C"), K1, INDIRECT("'[S2 Subcon IPC Log.xlsx]Subcon IPC Log'!"&"$D:$D"), "<="&K2) -> #REF! | N12: =ROUND(M12,1)=ROUND(J12,1) -> #REF! | O12: =J12-M12 -> #REF! | S12: 11
A13: B | B13: Cumulative Value of The Previous Payment : Öncəki ödənişlərin ümumi dəyəri: | J13: {=SUM(_xlfn.ANCHORARRAY(view_calc!D6)*_xlfn.ANCHORARRAY(view_calc!G6),IFERROR(_xlfn.ANCHORARRAY(view_calc!D62)*_xlfn.ANCHORARRAY(view_calc!G62),0),IFERROR(_xlfn.ANCHORARRAY(view_calc!D118)*_xlfn.ANCHORARRAY(view_calc!G118),0))} -> 729770.22 | S13: 12
A14: C | B14: Value of The Works Executed Within Current Period [A B] : Cari müddət [A B] ərzində görülmüş işlərin dəyəri: | J14: =J12-J13 -> 4901.7857 | M14: =SUMIFS( INDIRECT("'[S2 Subcon IPC Log.xlsx]Subcon IPC Log'!"&"$O:$O"), INDIRECT("'[S2 Subcon IPC Log.xlsx]Subcon IPC Log'!"&"$C:$C"), K1, INDIRECT("'[S2 Subcon IPC Log.xlsx]Subcon IPC Log'!"&"$D:$D"), K2) -> #REF! | N14: =IF(J14="","",ROUND(M14,1)=ROUND(J14,1)) -> #REF! | O14: =J14-M14 -> #REF! | S14: 13
A15: D | B15: Deductions Çıxılmalar | C15: Advance Payment: Avans ödənişi: | J15: =F22 -> 0 | S15: 14
C16: On Site Deductions (Lunch,fuel,etc): Sahə üzrə çıxılmalar (Yemək, yanacaq və s.)
C17: Delay Penalties: Yubanmaya görə cərimələr:
C18: Retention: Saxlanılma:
C19: Others: Digərləri:
C22: Total Amount (Deductions): Cəmi (Çıxılmalar): | F22: =SUM(F15:I21) -> 0
A23: E | B23: Net Payment: [ C D ] Xalis ödəniş: [ C D ] | J23: =J14-J15 -> 4901.7857
A24: Subcontractor Subpodratçı | D24: Technical Office Manager Texniki Şöbə Rəhbəri | G24: Site Manager Sahə Rəhbəri | J24: Approved by: Project Manager Təsdiqləyən şəxs: Layihə Rəhbəri
A25: …... / …... / 202….. | D25: …... / …... / 202….. | G25: …... / …... / 202….. | J25: …... / …... / 202…..
A29: =+C6 -> NAR TRANSPORT SERVICES MMC | D29: ERDİNÇ DELİBAŞI | G29: TURGAY BAL | J29: TEOMAN ULUDAĞ

Sheet view_calc
C1: Kolin Construction, Tourism, Industry and Trading Co. Inc. Kolin İnşaat, Turizm, Sənaye və Ticarət Co. Inc. | H1: Contract No | I1: =view__cover!K1 -> KLN-SPP2-AA-031 | N1: {=_xlfn._xlws.SORT(_xlfn.UNIQUE(_xlfn._xlws.FILTER(quantities!J:J,(quantities!D:D=contract_no)*(quantities!E:E<=ipc_no))))} -> 1 | Q1: =ROWS(_xlfn.ANCHORARRAY(N1)) -> 143
H2: IPC No | I2: =view__cover!$K$2 -> 14 | N2: 2
A3: Interim Payment Certificate Müvəqqəti Ödəniş Şəhadətnaməsi | J3: =view__cover!$N$1 -> Contract no: | K3: =contract_no -> 31 | N3: 3
A4: No | B4: Description of the Work İşin təsviri | C4: Unit Vahid | D4: Previous Quantity Önceki Kəmiyyət | E4: Current Quantity Hazirki Kəmiyyət | F4: Total Quantity Ümumi Kəmiyyət | G4: Unit Price Vahidin dəyəri | H4: Current Amount Hazırki Məbləğ | I4: Amount Məbləğ | J4: =view__cover!$N$2 -> IPC no | K4: =ipc_no -> 14 | N4: 4
D5: A | E5: B = C A | F5: C | G5: D | H5: F = B x D | I5: E = C x D | N5: 5
A6: {=_xlfn.TAKE(_xlfn.ANCHORARRAY(N1),50)} -> 1 | B6: {=_xlfn.XLOOKUP(contract_no&"-"&_xlfn.ANCHORARRAY(A6),log_prices!B:B,log_prices!F:F,,0)} -> SERVICE - 99LT168 - Baku-single | C6: {=_xlfn.XLOOKUP(contract_no&"-"&_xlfn.ANCHORARRAY(A6),log_prices!B:B,log_prices!G:G,,0)} -> single | D6: {=SUMIFS(quantities!G:G,quantities!D:D,contract_no,quantities!E:E,"<"&ipc_no,quantities!J:J,_xlfn.ANCHORARRAY(A6))} -> 57 | E6: {=_xlfn.ANCHORARRAY(F6)-_xlfn.ANCHORARRAY(D6)} -> 0 | F6: {=SUMIFS(quantities!G:G,quantities!D:D,contract_no,quantities!E:E,"<="&ipc_no,quantities!J:J,_xlfn.ANCHORARRAY(A6))} -> 57 | G6: {=_xlfn.XLOOKUP(contract_no&"-"&_xlfn.ANCHORARRAY(A6),log_prices!B:B,log_prices!I:I,,0)} -> 73.33 | H6: {=_xlfn.ANCHORARRAY(E6)*_xlfn.ANCHORARRAY(G6)} -> 0 | I6: {=_xlfn.ANCHORARRAY(F6)*_xlfn.ANCHORARRAY(G6)} -> 4179.81 | N6: 6
A7: 2 | B7: SERVICE - 99LT168 - Baku-hour | C7: hour | D7: 2 | E7: 0 | F7: 2 | G7: 7.333 | H7: 0 | I7: 14.666 | N7: 7
A8: 3 | B8: SERVICE - 99HZ395 - Sumqayıt-single | C8: single | D8: 384 | E8: 0 | F8: 384 | G8: 65 | H8: 0 | I8: 24960 | N8: 9
A9: 4 | B9: SERVICE - 99HZ395 - Sumqayıt-hour | C9: hour | D9: 369 | E9: 0 | F9: 369 | G9: 6.5 | H9: 0 | I9: 2398.5 | N9: 11
A10: 5 | B10: SERVICE - 90OV187 - Baku-single | C10: single | D10: 47 | E10: 0 | F10: 47 | G10: 73.33 | H10: 0 | I10: 3446.51 | N10: 12
A11: 6 | B11: SERVICE - 90OV187 - Baku-hour | C11: hour | D11: 49 | E11: 0 | F11: 49 | G11: 7.333 | H11: 0 | I11: 359.317 | N11: 13
A12: 7 | B12: SERVICE - 77UG347 - Sumqayıt-single | C12: single | D12: 6 | E12: 0 | F12: 6 | G12: 65 | H12: 0 | I12: 390 | N12: 15
A13: 9 | B13: SERVICE - 99FB123 - Baku-single | C13: single | D13: 6 | E13: 0 | F13: 6 | G13: 73.33 | H13: 0 | I13: 439.98 | N13: 16
A14: 11 | B14: SERVICE - 90ZP408 - Site-single | C14: single | D14: 97 | E14: 0 | F14: 97 | G14: 55.36 | H14: 0 | I14: 5369.92 | N14: 17
A15: 12 | B15: SERVICE - 90ZP408 - Site-hour | C15: hour | D15: 32.3 | E15: 0 | F15: 32.3 | G15: 5.536 | H15: 0 | I15: 178.8128 | N15: 19
A16: 13 | B16: SERVICE - 77AT386 - Procurement-single | C16: single | D16: 371 | E16: 0 | F16: 371 | G16: 46.67 | H16: 0 | I16: 17314.57 | N16: 20
A17: 15 | B17: SERVICE - 66CC029 - Site-single | C17: single | D17: 105 | E17: 0 | F17: 105 | G17: 55.36 | H17: 0 | I17: 5812.8 | N17: 21
A18: 16 | B18: SERVICE - 66CC029 - Site-hour | C18: hour | D18: 212 | E18: 0 | F18: 212 | G18: 5.536 | H18: 0 | I18: 1173.632 | N18: 22
... A55: 54 | B55: SERVICE - 53BD338 - Site-hour | C55: hour | D55: 70 | E55: 0 | F55: 70 | G55: 5.536 | H55: 0 | I55: 387.52 | N55: 60
N56: 61
A57: ="PAGE TOTAL (AZN)"&CHAR(10)&"SƏHİFƏNİN CƏMİ (AZN)" -> PAGE TOTAL (AZN) SƏHİFƏNİN CƏMİ (AZN) | H57: {=SUM(IFERROR(_xlfn._xlws.FILTER(H6:H56,H6:H56>0),0))} -> 0 | I57: {=SUM(_xlfn._xlws.FILTER(I6:I56,I6:I56>0))} -> 247385.95 | N57: 62
N58: 63
A59: =view__cover!A29 -> NAR TRANSPORT SERVICES MMC | C59: =_xlfn.LET(_xlpm.r,_xlfn.XLOOKUP(contract_no,log_contracts!B:B,log_contracts!G:G),IF(_xlpm.r=0,"",_xlpm.r)) -> İbrahim Kemik | E59: MEHMET TEVFİK ÇELİKKOL | H59: Mehmet Özgün DEDEKARGINOĞLU | N59: 65
A60: Subcontractor Subpodratçı | C60: Department Chief Bölmə Şefi | E60: Contract and Progress Payment Chief Ödəniş Sertifikatı Üzrə Məsul şəxs | H60: Technical Office Cheif Texniki Şöbə Şefi | N60: 67
A61: =IF(A62="","","PREVIOUS PAGE TOTAL (AZN)"&CHAR(10)&"ƏVVƏLKİ SƏHİFƏNİN CƏMİ (AZN)") -> PREVIOUS PAGE TOTAL (AZN) ƏVVƏLKİ SƏHİFƏNİN CƏMİ (AZN) | H61: =H57 -> 0 | I61: =I57 -> 247385.95 | N61: 68
A62: {=IFERROR(_xlfn.TAKE(_xlfn.DROP(_xlfn.ANCHORARRAY(N1),50),50),"")} -> 55 | B62: {=IFERROR(_xlfn.XLOOKUP(contract_no&"-"&_xlfn.ANCHORARRAY(A62),log_prices!B:B,log_prices!F:F,,0),"")} -> SERVICE - 53BD338 - Site-single | C62: {=IFERROR(_xlfn.XLOOKUP(contract_no&"-"&_xlfn.ANCHORARRAY(A62),log_prices!B:B,log_prices!G:G,,0),"")} -> single | D62: {=IFERROR(SUMIFS(quantities!G:G,quantities!D:D,contract_no,quantities!E:E,"<"&ipc_no,quantities!J:J,_xlfn.ANCHORARRAY(A62)),"")} -> 60 | E62: {=_xlfn.ANCHORARRAY(F62)-_xlfn.ANCHORARRAY(D62)} -> 0 | F62: {=IFERROR(SUMIFS(quantities!G:G,quantities!D:D,contract_no,quantities!E:E,"<="&ipc_no,quantities!J:J,_xlfn.ANCHORARRAY(A62)),"")} -> 60 | G62: {=IFERROR(_xlfn.XLOOKUP(contract_no&"-"&_xlfn.ANCHORARRAY(A62),log_prices!B:B,log_prices!I:I,,0),"")} -> 55.36 | H62: {=IFERROR(_xlfn.ANCHORARRAY(E62)*_xlfn.ANCHORARRAY(G62),"")} -> 0 | I62: {=IFERROR(_xlfn.ANCHORARRAY(F62)*_xlfn.ANCHORARRAY(G62),"")} -> 3321.6 | N62: 69
A63: 56 | B63: SERVICE - 55CB633 - Site-hour | C63: hour | D63: 797 | E63: 0 | F63: 797 | G63: 5.536 | H63: 0 | I63: 4412.192 | N63: 71
A64: 57 | B64: SERVICE - 55CB633 - Site-single | C64: single | D64: 345 | E64: 0 | F64: 345 | G64: 55.36 | H64: 0 | I64: 19099.2 | N64: 72
A65: 59 | B65: SERVICE - 77ET143 - Site-single | C65: single | D65: 85 | E65: 0 | F65: 85 | G65: 55.36 | H65: 0 | I65: 4705.6 | N65: 73
A66: 60 | B66: SERVICE - 77GM723 - Site-hour | C66: hour | D66: 81 | E66: 0 | F66: 81 | G66: 5.536 | H66: 0 | I66: 448.416 | N66: 74
A67: 61 | B67: SERVICE - 77GM723 - Site-single | C67: single | D67: 28 | E67: 0 | F67: 28 | G67: 55.36 | H67: 0 | I67: 1550.08 | N67: 75
A68: 62 | B68: SERVICE - 77GR998 - Site-double | C68: double | D68: 17 | E68: 0 | F68: 17 | G68: 91.339286 | H68: 0 | I68: 1552.7679 | N68: 76
A69: 63 | B69: SERVICE - 77GR998 - Site_v1-double | C69: double | D69: 243 | E69: 0 | F69: 243 | G69: 99.642857 | H69: 0 | I69: 24213.214 | N69: 77
A70: 65 | B70: SERVICE - 77GR998 - Site-single | C70: single | D70: 3 | E70: 0 | F70: 3 | G70: 55.357143 | H70: 0 | I70: 166.07143 | N70: 78
A71: 67 | B71: SERVICE - 77PV619 - Procurement-single | C71: single | D71: 120 | E71: 0 | F71: 120 | G71: 40 | H71: 0 | I71: 4800 | N71: 79
A72: 68 | B72: SERVICE - 77QE133 - Baku-hour | C72: hour | D72: 40 | E72: 0 | F72: 40 | G72: 7.333 | H72: 0 | I72: 293.32 | N72: 80
A73: 69 | B73: SERVICE - 77QE133 - Baku-single | C73: single | D73: 135 | E73: 0 | F73: 135 | G73: 73.33 | H73: 0 | I73: 9899.55 | N73: 81
A74: 71 | B74: SERVICE - 77RN868 - Baku-single | C74: single | D74: 41 | E74: 0 | F74: 41 | G74: 73.33 | H74: 0 | I74: 3006.53 | N74: 82
... A111: 110 | B111: SERVICE - 99OR961 - Site-hour | C111: hour | D111: 295 | E111: 0 | F111: 295 | G111: 5.536 | H111: 0 | I111: 1633.12 | N111: 122
N112: 123
...

Sheet view_daily_records
A1: {=_xlfn.LET( _xlpm.ipcData,_xlfn._xlws.SORT(_xlfn._xlws.FILTER(log_daily_records!B:AR,(log_daily_records!E:E=contract_no)*(log_daily_records!F:F=ipc_no)),3), _xlpm.plateNos,_xlfn.LET(_xlpm.r, _xlfn.UNIQUE(_xlfn.TAKE(_xlpm.ipcData,,3)),_xlfn.HSTACK(INDEX(_xlpm.r,,3), DATE(INDEX(_xlpm.r,,1), INDEX(_xlpm.r,,2), 1))), _xlpm.ph,_xlfn.LAMBDA(_xlpm.r,_xlpm.c,_xlfn.MAKEARRAY(_xlpm.r,_xlpm.c,_xlfn.LAMBDA(_xlpm.rl,_xlpm.cl,""))), _xlpm.makeBlock, _xlfn.LAMBDA(_xlpm.plateNo,_xlpm.monthYear, _xlfn.LET( _xlpm.data, _xlfn._xlws.FILTER(_xlpm.ipcData,(INDEX(_xlpm.ipcData,,3)=_xlpm.plateNo)*(INDEX(_xlpm.ipcData,,1)=YEAR(_xlpm.monthYear))*(INDEX(_xlpm.ipcData,,2)=MONTH(_xlpm.monthYear))), _xlfn.VSTACK( _xlfn.HSTACK(_xlfn.IMAGE("https://www.kolin.com.tr/Templates/Default/assets/img/logo.png","LOGO",1),_xlpm.ph(1,5),ipc_no), _xlfn.HSTACK("Plate number:",_xlpm.plateNo,"","Contract no: ","KLN-SPP2-"&_xlfn.XLOOKUP(contract_no,log_contracts!B:B,log_contracts!C:C)&"-"&TEXT(contract_no,"000"),"Date:",TEXT(_xlpm.monthYear,"mmm yy")), _xlfn.HSTACK(_xlpm.ph(1,7)), _xlfn.HSTACK("Date ","Start time","End time ","Time diff.","Start km","End km","Km diff."), _xlfn.IFNA(_xlfn.LET( _xlpm.getDataByType, _xlfn.LAMBDA(_xlpm.type, _xlfn.LET(_xlpm.r,IFERROR(_xlfn.TAKE(_xlfn.DROP(TRANSPOSE(_xlfn._xlws.FILTER(_xlpm.data, INDEX(_xlpm.data,,6)=_xlpm.type)),6),31),""),IF(_xlpm.r=0,"",_xlpm.r)) ), _xlpm.timeStart,_xlpm.getDataByType("time-start"), _xlpm.timeEnd,_xlpm.getDataByType("time-end"), _xlpm.kmStart,_xlpm.getDataByType("km-start"), _xlpm.kmEnd,_xlpm.getDataByType("km-end"), _xlfn.HSTACK( TEXT(_xlpm.monthYear-1+_xlfn.SEQUENCE(DAY(EOMONTH(_xlpm.monthYear,0))),"dd-mm-yyyy"), _xlpm.timeStart, _xlpm.timeEnd, _xlfn.LET(_xlpm.r, IFERROR((_xlpm.timeEnd-_xlpm.timeStart)*24-11,0), IF(_xlpm.r<=0,"",ROUND(_xlpm.r,0))), _xlpm.kmStart, _xlpm.kmEnd, _xlfn.LET(_xlpm.r, IFERROR((_xlpm.kmEnd-_xlpm.kmStart),0), IF(_xlpm.r=0,"",_xlpm.r)) ) ),""), _xlfn.LET( _xlpm.getTotal, _xlfn.LAMBDA(_xlpm.type,_xlpm.index, _xlfn.LET( _xlpm.r, IFERROR(INDEX(_xlfn._xlws.FILTER(_xlpm.data, INDEX(_xlpm.data,,6)=_xlpm.type),_xlpm.index),""), IF(_xlpm.r=0,"",_xlpm.r) ) ), _xlpm.single, _xlpm.getTotal("time-end",38), _xlpm.double, _xlpm.getTotal("time-end",39), _xlpm.hour,_xlpm.getTotal("time-end",40), _xlpm.km,_xlpm.getTotal("km-end",41), _xlfn.VSTACK( _xlfn.HSTACK("",IF(_xlpm.single="","","Total single"),IF(_xlpm.double="","","Total double"),IF(_xlpm.hour="","","Total hour"),IF(_xlpm.km="","","Total fuel"),"",""), _xlfn.HSTACK("",ROUND(_xlpm.single,1),_xlpm.double,_xlpm.hour,_xlpm.km,"",""), _xlpm.ph(1,7) ) ), _xlfn.HSTACK("","Subcontractor","","","Confirmed by","",""), _xlfn.HSTACK("",_xlfn.XLOOKUP(contract_no,log_contracts!B:B,log_contracts!E:E,,0),"","",_xlfn.TEXTJOIN(CHAR(10),TRUE,_xlfn.XLOOKUP(_xlpm.plateNo,log_prices!M:M,log_prices!O:O,,0)),"",""), _xlfn.HSTACK("","______________","","","______________","",""), _xlfn.HSTACK(_xlpm.ph(1,7)) ) ) ), _xlfn.REDUCE( "", _xlfn.SEQUENCE(ROWS(_xlpm.plateNos)), _xlfn.LAMBDA(_xlpm.acc,_xlpm.idx, _xlfn.LET( _xlpm.p, INDEX(_xlpm.plateNos, _xlpm.idx, 1), _xlpm.m, INDEX(_xlpm.plateNos, _xlpm.idx, 2), _xlpm.blk, _xlpm.makeBlock(_xlpm.p,_xlpm.m), IF(_xlpm.idx=1, _xlpm.blk, _xlfn.VSTACK(_xlpm.acc, _xlpm.blk)) ) ) ) )} -> #VALUE! | G1: 14 | I1: {=ROWS(_xlfn.UNIQUE(_xlfn._xlws.FILTER(log_daily_records!B:D,(log_daily_records!E:E=contract_no)*(log_daily_records!F:F=ipc_no))))} -> 1
A2: Plate number: | B2: 90GG153 | D2: Contract no: | E2: KLN-SPP2-AA-031 | F2: Date: | G2: Mar 26
A4: Date | B4: Start time | C4: End time | D4: Time diff. | E4: Start km | F4: End km | G4: Km diff.
A5: 01-03-2026 | B5: 0.33333333 | C5: 0.75
A6: 02-03-2026 | B6: 0.33333333 | C6: 0.75
A7: 03-03-2026 | B7: 0.33333333 | C7: 0.875 | D7: 2
A8: 04-03-2026 | B8: 0.33333333 | C8: 0.75
A9: 05-03-2026 | B9: 0.33333333 | C9: 0.75
A10: 06-03-2026 | B10: 0.33333333 | C10: 0.875 | D10: 2
A11: 07-03-2026 | B11: 0.33333333 | C11: 0.75
A12: 08-03-2026 | B12: 0.33333333 | C12: 0.75
A13: 09-03-2026 | B13: 0.33333333 | C13: 0.75
A14: 10-03-2026 | B14: 0.33333333 | C14: 0.875 | D14: 2
A15: 11-03-2026 | B15: 0.33333333 | C15: 0.75
A16: 12-03-2026 | B16: 0.33333333 | C16: 0.75
A17: 13-03-2026 | B17: 0.33333333 | C17: 0.875 | D17: 2
A18: 14-03-2026 | B18: 0.33333333 | C18: 0.75
A19: 15-03-2026 | B19: 0.33333333 | C19: 0.75
A20: 16-03-2026 | B20: 0.33333333 | C20: 0.75
A21: 17-03-2026 | B21: 0.33333333 | C21: 0.75
A22: 18-03-2026 | B22: 0.33333333 | C22: 0.75
A23: 19-03-2026 | B23: 0.33333333 | C23: 0.75
A24: 20-03-2026
A25: 21-03-2026
A26: 22-03-2026
A27: 23-03-2026
A28: 24-03-2026 | B28: 0.33333333 | C28: 0.75
A29: 25-03-2026 | B29: 0.33333333 | C29: 0.75
A30: 26-03-2026 | B30: 0.33333333 | C30: 0.75
A31: 27-03-2026 | B31: 0.33333333 | C31: 0.75
A32: 28-03-2026 | B32: 0.33333333 | C32: 0.75
A33: 29-03-2026 | B33: 0.33333333 | C33: 0.75
A34: 30-03-2026 | B34: 0.33333333 | C34: 0.875 | D34: 2
A35: 31-03-2026 | B35: 0.33333333 | C35: 0.75
B36: Total single | D36: Total hour
B37: 29 | D37: 15
B39: Subcontractor | E39: Confirmed by
B40: NAR TRANSPORT SERVICES MMC | E40: İrfan Karakaya
B41: ______________ | E41: ______________

Sheet view_monthly_records
D1: =view__cover!K1 -> KLN-SPP2-AA-031
A2: # | B2: Month | C2: IPC no | D2: Quantity | E2: Amount
A3: {=_xlfn.LET( _xlpm.data, _xlfn._xlws.SORT( _xlfn.LET( _xlpm.d, _xlfn._xlws.FILTER( log_monthly_records!B:M, (log_monthly_records!D:D=contract_no)*(log_monthly_records!E:E<=ipc_no)*(log_monthly_records!G:G<>0) ), _xlfn.HSTACK( DATE(INDEX(_xlpm.d,,1),INDEX(_xlpm.d,,2),1), INDEX(_xlpm.d,,4), INDEX(_xlpm.d,,6), INDEX(_xlpm.d,,12)*INDEX(_xlpm.d,,6), _xlfn.IFNA( SUBSTITUTE( INDEX(_xlpm.d,,11), " Hiz"&_xlfn.TEXTAFTER(INDEX(_xlpm.d,,11), " Hiz" ), "" ), INDEX(_xlpm.d,,11) ) ) ), 5 ), _xlfn.DROP( _xlfn.IFNA( _xlfn.REDUCE( "", _xlfn.LET( _xlpm.descs, _xlfn.UNIQUE(INDEX(_xlpm.data,,5)), _xlfn.VSTACK( _xlfn._xlws.FILTER( _xlpm.descs, LEFT(_xlpm.descs,9)<>"Retention" ), "Retention" ) ), _xlfn.LAMBDA(_xlpm.acc,_xlpm.cur, _xlfn.LET(_xlpm.x,_xlfn.TAKE( _xlfn._xlws.FILTER( _xlpm.data, LEFT(INDEX(_xlpm.data,,5),LEN(_xlpm.cur))=_xlpm.cur ),, 4 ),_xlfn.VSTACK( _xlpm.acc, _xlfn.HSTACK("",_xlpm.cur,"","",SUM(INDEX(_xlpm.x,,4))), _xlfn.HSTACK(_xlfn.SEQUENCE(ROWS(_xlpm.x)),_xlpm.x) )) ) ), "" ), 1 ) )} | B3: Mazot Ödemesi (15 lt - 18 lt / 100 km)-lt | E3: 142405.99
A4: 1 | B4: 45689 | C4: 1 | D4: 2956 | E4: 2956
A5: 2 | B5: 45717 | C5: 2 | D5: 11129.91 | E5: 11129.91
A6: 3 | B6: 45748 | C6: 3 | D6: 7666.74 | E6: 7666.74
A7: 4 | B7: 45778 | C7: 4 | D7: 7701.45 | E7: 7701.45
A8: 5 | B8: 45809 | C8: 5 | D8: 8670.24 | E8: 8670.24
A9: 6 | B9: 45839 | C9: 6 | D9: 7430.74 | E9: 7430.74
A10: 7 | B10: 45870 | C10: 7 | D10: 10262.76 | E10: 10262.76
A11: 8 | B11: 45901 | C11: 8 | D11: 11888.04 | E11: 11888.04
A12: 9 | B12: 45931 | C12: 9 | D12: 12646.8 | E12: 12646.8
A13: 10 | B13: 45962 | C13: 10 | D13: 12886.441 | E13: 12886.441
A14: 11 | B14: 45992 | C14: 11 | D14: 15693.78 | E14: 15693.78
A15: 12 | B15: 46023 | C15: 12 | D15: 16631.703 | E15: 16631.703
... A17: 14 | B17: 46082 | C17: 14 | D17: 0.1 | E17: 0.1
B18: SERVIS - 10RN527 - Sahə-saat | E18: 835.936
A19: 1 | B19: 45870 | C19: 7 | D19: 64 | E19: 354.304
A20: 2 | B20: 45901 | C20: 8 | D20: 67 | E20: 370.912
A21: 3 | B21: 45931 | C21: 9 | D21: 20 | E21: 110.72
B22: SERVIS - 10RN527 - Sahə-tək | E22: 3210.88
A23: 1 | B23: 45870 | C23: 7 | D23: 27 | E23: 1494.72
A24: 2 | B24: 45901 | C24: 8 | D24: 30 | E24: 1660.8
A25: 3 | B25: 45931 | C25: 9 | D25: 1 | E25: 55.36
B26: Retention | E26: -124426.47
A27: 1 | B27: 45689 | C27: 1 | D27: 2956 | E27: -2956
A28: 2 | B28: 45717 | C28: 2 | D28: 9319 | E28: -9319
A29: 3 | B29: 45748 | C29: 3 | D29: 6009 | E29: -6009
A30: 4 | B30: 45778 | C30: 4 | D30: 6357 | E30: -6357
A31: 5 | B31: 45809 | C31: 5 | D31: 6873.235 | E31: -6873.235
A32: 6 | B32: 45839 | C32: 6 | D32: 7221 | E32: -7221
A33: 7 | B33: 45870 | C33: 7 | D33: 8379.42 | E33: -8379.42
A34: 8 | B34: 45901 | C34: 8 | D34: 9645 | E34: -9645
A35: 9 | B35: 45931 | C35: 9 | D35: 10987 | E35: -10987
A36: 10 | B36: 45962 | C36: 10 | D36: 11358 | E36: -11358
A37: 11 | B37: 45992 | C37: 11 | D37: 13674.9 | E37: -13674.9
A38: 12 | B38: 46023 | C38: 12 | D38: 14029.1 | E38: -14029.1
... A43: 17 | B43: 45717 | C43: 2 | D43: 100 | E43: -100

Sheet view_fuel
F1: =view__cover!K1 -> KLN-SPP2-AA-031 | H1: =view__cover!K2 -> 14
A2: # | B2: Qeydiyyat nömrə nişanı | C2: Məsafə | D2: Litres per 100km | E2: Heablanmış miqdar A | F2: Hesablanmış məbləğ (AZN) | G2: Verilmiş yanacaq miqdarı B | H2: Verilmiş yanacaq məbləği (AZN) | I2: Diff. A-B
A3: {=_xlfn.LET( _xlpm.pnos,_xlfn._xlws.SORT(_xlfn.UNIQUE(_xlfn._xlws.FILTER(log_daily_records!D:D,(log_daily_records!E:E=contract_no)*(log_daily_records!F:F=ipc_no)))), _xlpm.distance,SUMIFS(log_daily_records!AS:AS,log_daily_records!D:D,_xlpm.pnos,log_daily_records!E:E,contract_no,log_daily_records!F:F,ipc_no), _xlpm.qs,SUMIFS(log_daily_records!AP:AP,log_daily_records!D:D,_xlpm.pnos,log_daily_records!E:E,contract_no,log_daily_records!F:F,ipc_no), _xlpm.provided,SUMIFS(log_fuel_provision!D:D,log_fuel_provision!C:C,_xlpm.pnos,log_fuel_provision!A:A,">="&ipc_date_start,log_fuel_provision!A:A,"<="&ipc_date_end), _xlpm.providedAmount,SUMIFS(log_fuel_provision!E:E,log_fuel_provision!C:C,_xlpm.pnos,log_fuel_provision!A:A,">="&ipc_date_start,log_fuel_provision!A:A,"<="&ipc_date_end), _xlfn.VSTACK( _xlfn.LET( _xlpm.d, _xlfn.HSTACK( _xlfn.SEQUENCE(ROWS(_xlpm.pnos)), _xlpm.pnos, _xlpm.distance, _xlfn.LET( _xlpm.r, MATCH(2,1/(log_daily_records!D:D<>""),1), _xlpm.d, log_daily_records!D2:INDEX(log_daily_records!D:D,_xlpm.r), _xlpm.e, log_daily_records!E2:INDEX(log_daily_records!E:E,_xlpm.r), _xlpm.F, log_daily_records!F2:INDEX(log_daily_records!F:F,_xlpm.r), _xlpm.G, log_daily_records!G2:INDEX(log_daily_records!G:G,_xlpm.r), _xlpm.AQ,log_daily_records!AQ2:INDEX(log_daily_records!AQ:AQ,_xlpm.r), _xlfn.MAP(_xlpm.pnos,_xlfn.LAMBDA(_xlpm.pn,_xlfn.XLOOKUP(1,(_xlpm.d=_xlpm.pn)*(_xlpm.e=contract_no)*(_xlpm.F=ipc_no)*(_xlpm.G="km-end"),_xlpm.AQ,"",0))) ), _xlpm.qs, _xlpm.qs*1.1, IF(_xlpm.qs=0,"",_xlpm.provided), IF(_xlpm.qs=0,"",_xlpm.providedAmount), _xlpm.qs-_xlpm.provided ), _xlfn.VSTACK( _xlfn._xlws.FILTER(_xlpm.d,INDEX(_xlpm.d,,4)<>""), _xlfn.HSTACK("","","","","",SUM(INDEX(_xlpm.d,,6)),"",SUM(INDEX(_xlpm.d,,8)),"") ) ), _xlfn.HSTACK("","","","","","","","",""), _xlfn.HSTACK("","Subcontractor","","","","","Confirmed by","",""), _xlfn.HSTACK("",_xlfn.XLOOKUP(contract_no,log_contracts!B:B,log_contracts!E:E,,0),"","","","",_xlfn.TEXTJOIN(CHAR(10),TRUE,_xlfn.XLOOKUP(contract_no,log_contracts!B:B,log_contracts!G:G)),"",""), _xlfn.HSTACK("","______________","","","","","______________","","") ) )} -> #VALUE!
K4: =F4-H4 -> 0

Sheet log_monthly_records
A1: # | B1: year | C1: month | D1: contract no | E1: ipc no | F1: plate no | G1: quantity | H1: price type | I1: notes | J1: price no | K1: Price no select | L1: price description | M1: Price
A2: {=_xlfn.SEQUENCE(ROWS(_xlfn._TRO_TRAILING(C:C))-1)} -> 1 | B2: 2024 | C2: 12 | D2: 11 | E2: 1 | G2: 1 | J2: 1 | K2: 1 | L2: Aylıq Ücret | M2: 5500
A3: 2 | B3: 2024 | C3: 12 | D3: 11 | E3: 1 | G3: 8 | J3: 2 | K3: 2 | L3: Elave Ücret | M3: 200
A4: 3 | B4: 2024 | C4: 12 | D4: 11 | E4: 1 | G4: 12 | J4: 3 | K4: 3 | L4: Armatür Test (Tensile st., Yield st., Elangation) | M4: 100
A5: 4 | B5: 2025 | C5: 2 | D5: 11 | E5: 2 | G5: 1 | J5: 1 | K5: 1 | L5: Aylıq Ücret | M5: 5500
A6: 5 | B6: 2025 | C6: 2 | D6: 11 | E6: 2 | G6: 3.1 | J6: 2 | K6: 2 | L6: Elave Ücret | M6: 200
A7: 6 | B7: 2025 | C7: 2 | D7: 11 | E7: 2 | G7: 18 | J7: 3 | K7: 3 | L7: Armatür Test (Tensile st., Yield st., Elangation) | M7: 100
A8: 7 | B8: 2025 | C8: 2 | D8: 11 | E8: 2 | G8: 1 | J8: 4 | K8: 4 | L8: Su Testi | M8: 300
A9: 8 | B9: 2025 | C9: 2 | D9: 11 | E9: 2 | G9: 1 | J9: 5 | K9: 5 | L9: Kaynak Testi | M9: 540
A10: 9 | B10: 2025 | C10: 3 | D10: 11 | E10: 3 | G10: 1 | J10: 1 | K10: 1 | L10: Aylıq Ücret | M10: 5500
A11: 10 | B11: 2025 | C11: 3 | D11: 11 | E11: 3 | G11: 13 | J11: 2 | K11: 2 | L11: Elave Ücret | M11: 200
A12: 11 | B12: 2025 | C12: 3 | D12: 11 | E12: 3 | G12: 14 | J12: 3 | K12: 3 | L12: Armatür Test (Tensile st., Yield st., Elangation) | M12: 100
A13: 12 | B13: 2025 | C13: 3 | D13: 11 | E13: 3 | G13: 1 | J13: 6 | K13: 6 | L13: Ultrasonic Pulse Echo (Betonarme) | M13: 1000
A14: 13 | B14: 2025 | C14: 3 | D14: 11 | E14: 3 | G14: 4 | J14: 7 | K14: 7 | L14: Armatür Test (Bend) | M14: 110
... A99: 98 | B99: 2025 | C99: 11 | D99: 30 | E99: 11 | G99: 1 | J99: 4 | K99: 4 | L99: AMBULANCE - 99JE233 | M99: 5500
A100: 99 | B100: 2025 | C100: 2 | D100: 31 | E100: 1 | G100: 2956 | J100: M-1 | K100: M-1 | L100: Mazot Ödemesi (15 lt - 18 lt / 100 km)-lt | M100: 1
A101: 100 | B101: 2025 | C101: 2 | D101: 31 | E101: 1 | G101: 2956 | J101: R-1 | K101: R-1 | L101: Retention - Fuel Reduction | M101: -1
A102: 101 | B102: 2025 | C102: 3 | D102: 31 | E102: 2 | G102: =SUMIFS(log_daily_records!AP:AP,log_daily_records!E:E,D102,log_daily_records!F:F,E102) -> 11129.91 | J102: M-1 | K102: M-1 | L102: Mazot Ödemesi (15 lt - 18 lt / 100 km)-lt | M102: 1
A103: 102 | B103: 2025 | C103: 3 | D103: 31 | E103: 2 | G103: 9319 | J103: R-1 | K103: R-1 | L103: Retention - Fuel Reduction | M103: -1
A104: 103 | B104: 2025 | C104: 3 | D104: 31 | E104: 2 | G104: 100 | J104: R-2 | K104: R-2 | L104: Retention - SƏTƏMM Cərimə Kesintisi (İSG) | M104: -1
A105: 104 | B105: 2025 | C105: 4 | D105: 31 | E105: 3 | G105: =SUMIFS(log_daily_records!AP:AP,log_daily_records!E:E,D105,log_daily_records!F:F,E105) -> 7666.74 | J105: M-1 | K105: M-1 | L105: Mazot Ödemesi (15 lt - 18 lt / 100 km)-lt | M105: 1
A106: 105 | B106: 2025 | C106: 4 | D106: 31 | E106: 3 | G106: 6009 | J106: R-1 | K106: R-1 | L106: Retention - Fuel Reduction | M106: -1
A107: 106 | B107: 2025 | C107: 5 | D107: 31 | E107: 4 | G107: =SUMIFS(log_daily_records!AP:AP,log_daily_records!E:E,D107,log_daily_records!F:F,E107) -> 7701.45 | J107: M-1 | K107: M-1 | L107: Mazot Ödemesi (15 lt - 18 lt / 100 km)-lt | M107: 1
A108: 107 | B108: 2025 | C108: 5 | D108: 31 | E108: 4 | G108: 6357 | J108: R-1 | K108: R-1 | L108: Retention - Fuel Reduction | M108: -1
A109: 108 | B109: 2025 | C109: 6 | D109: 31 | E109: 5 | G109: =SUMIFS(log_daily_records!AP:AP,log_daily_records!E:E,D109,log_daily_records!F:F,E109) -> 8670.24 | J109: M-1 | K109: M-1 | L109: Mazot Ödemesi (15 lt - 18 lt / 100 km)-lt | M109: 1
A110: 109 | B110: 2025 | C110: 6 | D110: 31 | E110: 5 | G110: 6873.235 | J110: R-1 | K110: R-1 | L110: Retention - Fuel Reduction | M110: -1
A111: 110 | B111: 2025 | C111: 7 | D111: 31 | E111: 6 | G111: =SUMIFS(log_daily_records!AP:AP,log_daily_records!E:E,D111,log_daily_records!F:F,E111)-751.13 -> 7430.74 | I111: added 751.5 from June 2025 | J111: M-1 | K111: M-1 | L111: Mazot Ödemesi (15 lt - 18 lt / 100 km)-lt | M111: 1
A112: 111 | B112: 2025 | C112: 7 | D112: 31 | E112: 6 | G112: 7221 | J112: R-1 | K112: R-1 | L112: Retention - Fuel Reduction | M112: -1
A113: 112 | B113: 2025 | C113: 8 | D113: 31 | E113: 7 | F113: 10RN527 | G113: 27 | J113: 31 | K113: 31 | L113: SERVIS - 10RN527 - Sahə-tək | M113: 55.36
A114: 113 | B114: 2025 | C114: 8 | D114: 31 | E114: 7 | F114: 10RN527 | G114: 64 | J114: 29 | K114: 29 | L114: SERVIS - 10RN527 - Sahə-saat | M114: 5.536
A115: 114 | B115: 2025 | C115: 8 | D115: 31 | E115: 7 | G115: =SUMIFS(log_daily_records!AP:AP,log_daily_records!E:E,D115,log_daily_records!F:F,E115)+140 -> 10262.76 | I115: added 140 from July 2025 | J115: M-1 | K115: M-1 | L115: Mazot Ödemesi (15 lt - 18 lt / 100 km)-lt | M115: 1
A116: 115 | B116: 2025 | C116: 8 | D116: 31 | E116: 7 | G116: 8379.42 | J116: R-1 | K116: R-1 | L116: Retention - Fuel Reduction | M116: -1
A117: 116 | B117: 2025 | C117: 9 | D117: 31 | E117: 8 | F117: 10RN527 | G117: 30 | H117: single | J117: 31 | K117: 31 | L117: SERVIS - 10RN527 - Sahə-tək | M117: 55.36
A118: 117 | B118: 2025 | C118: 9 | D118: 31 | E118: 8 | F118: 10RN527 | G118: 67 | H118: hour | J118: 29 | K118: 29 | L118: SERVIS - 10RN527 - Sahə-saat | M118: 5.536
A119: 118 | B119: 2025 | C119: 9 | D119: 31 | E119: 8 | G119: =SUMIFS(log_daily_records!AP:AP,log_daily_records!E:E,D119,log_daily_records!F:F,E119) -> 11888.04 | J119: M-1 | K119: M-1 | L119: Mazot Ödemesi (15 lt - 18 lt / 100 km)-lt | M119: 1
A120: 119 | B120: 2025 | C120: 9 | D120: 31 | E120: 8 | G120: 9645 | J120: R-1 | K120: R-1 | L120: Retention - Fuel Reduction | M120: -1
A121: 120 | B121: 2025 | C121: 10 | D121: 31 | E121: 9 | F121: 10RN527 | G121: 1 | H121: single | J121: 31 | K121: 31 | L121: SERVIS - 10RN527 - Sahə-tək | M121: 55.36
A122: 121 | B122: 2025 | C122: 10 | D122: 31 | E122: 9 | F122: 10RN527 | G122: 20 | H122: hour | I122: mistakenly calculated | J122: 29 | K122: 29 | L122: SERVIS - 10RN527 - Sahə-saat | M122: 5.536
A123: 122 | B123: 2025 | C123: 10 | D123: 31 | E123: 9 | G123: =SUMIFS(log_daily_records!AP:AP,log_daily_records!E:E,D123,log_daily_records!F:F,E123) -> 12646.8 | J123: M-1 | K123: M-1 | L123: Mazot Ödemesi (15 lt - 18 lt / 100 km)-lt | M123: 1
A124: 123 | B124: 2025 | C124: 10 | D124: 31 | E124: 9 | G124: 10987 | J124: R-1 | K124: R-1 | L124: Retention - Fuel Reduction | M124: -1
...

Sheet log_daily_records
A1: # =LET(hourRow,COUNTA($A:$A)+2,start,INDIRECT("H"&ROW()-1&":AL"&ROW()-1),IF(start="","",start+10/24+IFERROR(INDIRECT("H"&hourRow&":AL"&hourRow),0)/24)) | B1: year | C1: month | D1: plateno | E1: conctract no | F1: ipc no | G1: type | H1: 1 | I1: 2 | J1: 3 | K1: 4 | L1: 5 | M1: 6 | N1: 7 | O1: 8 | P1: 9 | Q1: 10 | R1: 11 | S1: 12 | T1: 13 | U1: 14 | V1: 15 | W1: 16 | X1: 17 | Y1: 18 | Z1: 19 | AA1: 20 | AB1: 21 | AC1: 22 | AD1: 23 | AE1: 24 | AF1: 25 | AG1: 26 | AH1: 27 | AI1: 28 | AJ1: 29 | AK1: 30 | AL1: 31 | AM1: Single | AN1: Double | AO1: Hours | AP1: Calc. fuel | AQ1: 100km/lt | AR1: Notes | AS1: Diff. dist.
A2: 1 | B2: 2025 | C2: 1 | D2: 99AS882 | E2: 30 | F2: 1 | G2: time-start | AC2: 0.29166667 | AD2: 0.29166667 | AE2: 0.29166667 | AF2: 0.29166667 | AG2: 0.29166667 | AH2: 0.29166667 | AI2: 0.29166667 | AJ2: 0.29166667 | AK2: 0.29166667 | AL2: 0.29166667
A3: 2 | B3: 2025 | C3: 1 | D3: 99AS882 | E3: 30 | F3: 1 | G3: time-end | AC3: 0.75 | AD3: 0.75 | AE3: 0.75 | AF3: 0.75 | AG3: 0.79166667 | AH3: 0.79166667 | AI3: 0.75 | AJ3: 0.75 | AK3: 0.75 | AL3: 0.75 | AM3: 10
A4: 3 | B4: 2025 | C4: 2 | D4: 99AS882 | E4: 30 | F4: 2 | G4: time-start | H4: 0.29166667 | I4: 0.29166667 | J4: 0.29166667 | K4: 0.29166667 | L4: 0.29166667 | M4: 0.29166667 | N4: 0.29166667 | O4: 0.29166667 | P4: 0.29166667 | Q4: 0.29166667 | R4: 0.29166667 | S4: 0.29166667 | T4: 0.29166667 | U4: 0.29166667 | V4: 0.29166667 | W4: 0.29166667 | X4: 0.29166667 | Y4: 0.29166667 | Z4: 0.29166667 | AA4: 0.29166667 | AB4: 0.29166667 | AC4: 0.29166667 | AD4: 0.29166667 | AE4: 0.29166667 | AF4: 0.29166667 | AG4: 0.29166667 | AH4: 0.29166667 | AI4: 0.29166667
A5: 4 | B5: 2025 | C5: 2 | D5: 99AS882 | E5: 30 | F5: 2 | G5: time-end | H5: 0.75 | I5: 0.75 | J5: 0.75 | K5: 0.75 | L5: 0.75 | M5: 0.75 | N5: 0.75 | O5: 0.75 | P5: 0.75 | Q5: 0.75 | R5: 0.75 | S5: 0.75 | T5: 0.75 | U5: 0.75 | V5: 0.75 | W5: 0.75 | X5: 0.75 | Y5: 0.75 | Z5: 0.75 | AA5: 0.75 | AB5: 0.75 | AC5: 0.75 | AD5: 0.75 | AE5: 0.75 | AF5: 0.75 | AG5: 0.79166667 | AH5: 0.79166667 | AI5: 0.75 | AM5: 30
A6: 5 | B6: 2025 | C6: 2 | D6: 99JE233 | E6: 30 | F6: 2 | G6: time-start | H6: 0.29166667 | I6: 0.29166667 | J6: 0.29166667 | K6: 0.29166667 | L6: 0.29166667 | M6: 0.29166667 | N6: 0.29166667 | O6: 0.29166667 | P6: 0.29166667 | Q6: 0.29166667 | R6: 0.29166667 | S6: 0.29166667 | T6: 0.29166667 | U6: 0.29166667 | V6: 0.29166667 | W6: 0.29166667 | X6: 0.29166667 | Y6: 0.29166667 | Z6: 0.29166667 | AA6: 0.29166667 | AB6: 0.29166667 | AC6: 0.29166667 | AD6: 0.29166667 | AE6: 0.29166667 | AF6: 0.29166667 | AG6: 0.29166667 | AH6: 0.29166667 | AI6: 0.29166667
A7: 6 | B7: 2025 | C7: 2 | D7: 99JE233 | E7: 30 | F7: 2 | G7: time-end | H7: 0.75 | I7: 0.75 | J7: 0.75 | K7: 0.75 | L7: 0.75 | M7: 0.75 | N7: 0.75 | O7: 0.75 | P7: 0.75 | Q7: 0.75 | R7: 0.75 | S7: 0.75 | T7: 0.75 | U7: 0.75 | V7: 0.75 | W7: 0.75 | X7: 0.75 | Y7: 0.75 | Z7: 0.75 | AA7: 0.75 | AB7: 0.75 | AC7: 0.75 | AD7: 0.75 | AE7: 0.75 | AF7: 0.75 | AG7: 0.79166667 | AH7: 0.79166667 | AI7: 0.75 | AM7: 30
A8: 7 | B8: 2025 | C8: 1 | D8: 99LT168 | E8: 31 | F8: 1 | G8: time-start | AE8: 0.29166667 | AF8: 0.29166667 | AG8: 0.29166667 | AH8: 0.29166667 | AI8: 0.29166667 | AJ8: 0.29166667 | AK8: 0.29166667 | AL8: 0.29166667
A9: 8 | B9: 2025 | C9: 1 | D9: 99LT168 | E9: 31 | F9: 1 | G9: time-end | AE9: 0.75 | AF9: 0.75 | AG9: 0.75 | AH9: 0.75 | AI9: 0.75 | AJ9: 0.75 | AK9: 0.75 | AL9: 0.75 | AM9: 8
A10: 9 | B10: 2025 | C10: 2 | D10: 99LT168 | E10: 31 | F10: 1 | G10: time-start | H10: 0.29166667 | I10: 0.29166667 | J10: 0.29166667 | K10: 0.29166667 | L10: 0.29166667 | M10: 0.29166667 | N10: 0.29166667 | O10: 0.29166667 | P10: 0.29166667 | Q10: 0.29166667 | R10: 0.29166667 | S10: 0.29166667 | T10: 0.29166667 | U10: 0.29166667 | V10: 0.29166667 | W10: 0.29166667 | X10: 0.29166667 | Y10: 0.29166667 | Z10: 0.29166667 | AA10: 0.29166667 | AB10: 0.29166667 | AC10: 0.29166667 | AD10: 0.29166667 | AE10: 0.29166667 | AF10: 0.29166667 | AG10: 0.29166667 | AH10: 0.29166667 | AI10: 0.29166667
A11: 10 | B11: 2025 | C11: 2 | D11: 99LT168 | E11: 31 | F11: 1 | G11: time-end | H11: 0.75 | I11: 0.75 | J11: 0.75 | K11: 0.75 | L11: 0.75 | M11: 0.75 | N11: 0.75 | O11: 0.75 | P11: 0.75 | Q11: 0.75 | R11: 0.75 | S11: 0.75 | T11: 0.75 | U11: 0.75 | V11: 0.75 | W11: 0.75 | X11: 0.75 | Y11: 0.75 | Z11: 0.75 | AA11: 0.75 | AB11: 0.75 | AC11: 0.75 | AD11: 0.75 | AE11: 0.75 | AF11: 0.75 | AG11: 0.79166667 | AH11: 0.79166667 | AI11: 0.75 | AM11: 28 | AO11: 2
A12: 11 | B12: 2025 | C12: 1 | D12: 99HZ395 | E12: 31 | F12: 1 | G12: time-start | AJ12: 0.29166667 | AK12: 0.29166667 | AL12: 0.29166667
A13: 12 | B13: 2025 | C13: 1 | D13: 99HZ395 | E13: 31 | F13: 1 | G13: time-end | AJ13: 0.75 | AK13: 0.75 | AL13: 0.75 | AM13: 3
A14: 13 | B14: 2025 | C14: 2 | D14: 99HZ395 | E14: 31 | F14: 1 | G14: time-start | H14: 0.29166667 | I14: 0.29166667 | J14: 0.29166667 | K14: 0.29166667 | L14: 0.29166667 | M14: 0.29166667 | N14: 0.29166667 | O14: 0.29166667 | P14: 0.29166667 | Q14: 0.29166667 | R14: 0.29166667 | S14: 0.29166667 | T14: 0.29166667 | U14: 0.29166667 | V14: 0.29166667 | W14: 0.29166667 | X14: 0.29166667 | Y14: 0.29166667 | Z14: 0.29166667 | AA14: 0.29166667 | AB14: 0.29166667 | AC14: 0.29166667 | AD14: 0.29166667 | AE14: 0.29166667 | AF14: 0.29166667 | AG14: 0.29166667 | AH14: 0.29166667 | AI14: 0.29166667
A15: 14 | B15: 2025 | C15: 2 | D15: 99HZ395 | E15: 31 | F15: 1 | G15: time-end | H15: 0.75 | I15: 0.75 | J15: 0.75 | K15: 0.75 | L15: 0.75 | M15: 0.75 | N15: 0.75 | O15: 0.75 | P15: 0.75 | Q15: 0.75 | R15: 0.75 | S15: 0.75 | T15: 0.75 | U15: 0.75 | V15: 0.75 | W15: 0.75 | X15: 0.75 | Y15: 0.75 | Z15: 0.75 | AA15: 0.75 | AB15: 0.75 | AC15: 0.75 | AD15: 0.75 | AE15: 0.75 | AF15: 0.75 | AG15: 0.75 | AH15: 0.75 | AI15: 0.75 | AM15: 28
A16: 15 | B16: 2025 | C16: 2 | D16: 99FB123 | E16: 31 | F16: 1 | G16: time-start | M16: 0.29166667 | N16: 0.29166667 | O16: 0.29166667 | P16: 0.29166667 | Q16: 0.29166667 | R16: 0.29166667
A17: 16 | B17: 2025 | C17: 2 | D17: 99FB123 | E17: 31 | F17: 1 | G17: time-end | M17: 0.75 | N17: 0.75 | O17: 0.75 | P17: 0.75 | Q17: 0.75 | R17: 0.75 | AM17: 6
A18: 17 | B18: 2025 | C18: 2 | D18: 90OV187 | E18: 31 | F18: 1 | G18: time-start | S18: 0.29166667 | T18: 0.29166667 | U18: 0.29166667 | V18: 0.29166667 | W18: 0.29166667 | X18: 0.29166667 | Y18: 0.29166667 | Z18: 0.29166667 | AA18: 0.29166667 | AB18: 0.29166667 | AC18: 0.29166667 | AD18: 0.29166667 | AE18: 0.29166667 | AF18: 0.29166667 | AG18: 0.29166667 | AH18: 0.29166667 | AI18: 0.29166667
A19: 18 | B19: 2025 | C19: 2 | D19: 90OV187 | E19: 31 | F19: 1 | G19: time-end | S19: 0.75 | T19: 0.75 | U19: 0.75 | V19: 0.75 | W19: 0.75 | X19: 0.75 | Y19: 0.75 | Z19: 0.75 | AA19: 0.75 | AB19: 0.75 | AC19: 0.75 | AD19: 0.75 | AE19: 0.75 | AF19: 0.75 | AG19: 0.75 | AH19: 0.75 | AI19: 0.75 | AM19: 17
A20: 19 | B20: 2025 | C20: 2 | D20: 77UG347 | E20: 31 | F20: 1 | G20: time-start | H20: 0.29166667 | I20: 0.29166667 | J20: 0.29166667 | K20: 0.29166667 | AK20: 0.29166667 | AL20: 0.29166667
A21: 20 | B21: 2025 | C21: 2 | D21: 77UG347 | E21: 31 | F21: 1 | G21: time-end | H21: 0.75 | I21: 0.75 | J21: 0.75 | K21: 0.75 | AK21: 0.75 | AL21: 0.75 | AM21: 6
A22: 21 | B22: 2025 | C22: 2 | D22: 90ZP408 | E22: 31 | F22: 1 | G22: time-start | K22: 0.29166667 | L22: 0.29166667 | M22: 0.29166667 | N22: 0.29166667 | O22: 0.29166667 | P22: 0.29166667 | X22: 0.29166667 | Y22: 0.29166667 | Z22: 0.29166667 | AA22: 0.29166667 | AB22: 0.29166667 | AC22: 0.29166667 | AE22: 0.29166667 | AF22: 0.29166667 | AG22: 0.29166667 | AH22: 0.29166667 | AI22: 0.29166667
A23: 22 | B23: 2025 | C23: 2 | D23: 90ZP408 | E23: 31 | F23: 1 | G23: time-end | K23: 0.79166667 | L23: 0.79166667 | M23: 0.79166667 | N23: 0.79166667 | O23: 0.79166667 | P23: 0.79166667 | X23: 0.79166667 | Y23: 0.79166667 | Z23: 0.79166667 | AA23: 0.79166667 | AB23: 0.79166667 | AC23: 0.79166667 | AE23: 0.79166667 | AF23: 0.79166667 | AG23: 0.79166667 | AH23: 0.79166667 | AI23: 0.79166667 | AM23: 17 | AO23: 17
A24: 23 | B24: 2025 | C24: 2 | D24: 66CC029 | E24: 31 | F24: 1 | G24: time-start | Q24: 0.29166667 | R24: 0.29166667 | S24: 0.29166667 | T24: 0.29166667 | U24: 0.29166667 | V24: 0.29166667 | W24: 0.29166667 | X24: 0.29166667 | Y24: 0.29166667 | Z24: 0.29166667 | AA24: 0.29166667 | AB24: 0.29166667 | AC24: 0.29166667 | AD24: 0.29166667 | AE24: 0.29166667 | AF24: 0.29166667 | AG24: 0.29166667 | AH24: 0.29166667 | AI24: 0.29166667
A25: 24 | B25: 2025 | C25: 2 | D25: 66CC029 | E25: 31 | F25: 1 | G25: time-end | Q25: 0.79166667 | R25: 0.79166667 | S25: 0.79166667 | T25: 0.79166667 | U25: 0.79166667 | V25: 0.79166667 | W25: 0.79166667 | X25: 0.79166667 | Y25: 0.79166667 | Z25: 0.79166667 | AA25: 0.79166667 | AB25: 0.79166667 | AC25: 0.79166667 | AD25: 0.79166667 | AE25: 0.79166667 | AF25: 0.79166667 | AG25: 0.79166667 | AH25: 0.79166667 | AI25: 0.79166667 | AM25: 19 | AO25: 19
A26: 25 | B26: 2025 | C26: 2 | D26: 77QK725 | E26: 31 | F26: 1 | G26: time-start | AC26: 0.29166667 | AD26: 0.29166667 | AE26: 0.29166667 | AF26: 0.29166667 | AG26: 0.29166667 | AH26: 0.29166667 | AI26: 0.29166667
A27: 26 | B27: 2025 | C27: 2 | D27: 77QK725 | E27: 31 | F27: 1 | G27: time-end | AC27: 0.75 | AD27: 0.75 | AE27: 0.75 | AF27: 0.75 | AG27: 0.75 | AH27: 0.75 | AI27: 0.75 | AM27: 7
A28: 27 | B28: 2025 | C28: 2 | D28: 77AT386 | E28: 31 | F28: 1 | G28: time-start | AA28: 0.29166667 | AB28: 0.29166667 | AC28: 0.29166667 | AD28: 0.29166667 | AE28: 0.29166667 | AF28: 0.29166667 | AG28: 0.29166667 | AH28: 0.29166667 | AI28: 0.29166667
A29: 28 | B29: 2025 | C29: 2 | D29: 77AT386 | E29: 31 | F29: 1 | G29: time-end | AA29: 0.75 | AB29: 0.75 | AC29: 0.75 | AD29: 0.75 | AE29: 0.75 | AF29: 0.75 | AG29: 0.75 | AH29: 0.75 | AI29: 0.75 | AM29: 9
A30: 29 | B30: 2025 | C30: 3 | D30: 99LT168 | E30: 31 | F30: 2 | G30: time-start | J30: 0.29166667 | K30: 0.29166667 | L30: 0.29166667 | M30: 0.29166667 | N30: 0.29166667 | O30: 0.29166667 | Q30: 0.29166667 | R30: 0.29166667 | S30: 0.29166667 | T30: 0.29166667 | U30: 0.29166667 | V30: 0.29166667 | X30: 0.29166667 | Y30: 0.29166667 | Z30: 0.29166667 | AE30: 0.29166667 | AF30: 0.29166667 | AG30: 0.29166667 | AH30: 0.29166667 | AI30: 0.29166667 | AJ30: 0.29166667
A31: 30 | B31: 2025 | C31: 3 | D31: 99LT168 | E31: 31 | F31: 2 | G31: time-end | J31: 0.75 | K31: 0.75 | L31: 0.75 | M31: 0.75 | N31: 0.75 | O31: 0.75 | Q31: 0.75 | R31: 0.75 | S31: 0.75 | T31: 0.75 | U31: 0.75 | V31: 0.75 | X31: 0.75 | Y31: 0.75 | Z31: 0.75 | AE31: 0.75 | AF31: 0.75 | AG31: 0.75 | AH31: 0.75 | AI31: 0.75 | AJ31: 0.75 | AM31: 21
A32: 31 | B32: 2025 | C32: 3 | D32: 99LT168 | E32: 31 | F32: 2 | G32: km-start | J32: 219057 | K32: 219368 | L32: 219608 | M32: 219832 | N32: 220225 | O32: 220150 | Q32: 220868 | R32: 221134 | S32: 221355 | T32: 221572 | U32: 221882 | V32: 222106 | X32: 222358 | Y32: 222609 | Z32: 222962 | AE32: 224762 | AF32: 224988 | AG32: 225232 | AH32: 225450 | AI32: 225714 | AJ32: 225934
A33: 32 | B33: 2025 | C33: 3 | D33: 99LT168 | E33: 31 | F33: 2 | G33: km-end | J33: 219318 | K33: 219583 | L33: 219832 | M33: 220225 | N33: 220450 | O33: 220678 | Q33: 221090 | R33: 221355 | S33: 221572 | T33: 221882 | U33: 222106 | V33: 222312 | X33: 222608 | Y33: 222832 | Z33: 223187 | AE33: 224988 | AF33: 225232 | AG33: 225449 | AH33: 225674 | AI33: 225931 | AJ33: 226148 | AP33: 951.48 | AQ33: 18 | AS33: 5286
A34: 33 | B34: 2025 | C34: 3 | D34: 90OV187 | E34: 31 | F34: 2 | G34: time-start | H34: 0.29166667 | I34: 0.29166667 | J34: 0.29166667 | K34: 0.29166667 | L34: 0.29166667 | M34: 0.29166667 | N34: 0.29166667 | O34: 0.29166667 | P34: 0.29166667 | Q34: 0.29166667 | R34: 0.29166667 | S34: 0.29166667 | T34: 0.29166667 | U34: 0.29166667 | V34: 0.29166667 | W34: 0.29166667 | X34: 0.29166667 | Y34: 0.29166667 | Z34: 0.29166667 | AA34: 0.29166667 | AB34: 0.29166667 | AC34: 0.29166667 | AD34: 0.29166667 | AE34: 0.29166667 | AF34: 0.29166667 | AG34: 0.29166667 | AH34: 0.29166667 | AI34: 0.29166667 | AJ34: 0.29166667 | AK34: 0.29166667
A35: 34 | B35: 2025 | C35: 3 | D35: 90OV187 | E35: 31 | F35: 2 | G35: time-end | H35: 0.75 | I35: 0.75 | J35: 0.75 | K35: 0.75 | L35: 0.75 | M35: 0.75 | N35: 0.75 | O35: 0.75 | P35: 0.75 | Q35: 0.75 | R35: 0.75 | S35: 0.75 | T35: 0.75 | U35: 0.75 | V35: 0.83333333 | W35: 0.85416667 | X35: 0.85416667 | Y35: 0.79166667 | Z35: 0.79166667 | AA35: 0.83333333 | AB35: 0.91666667 | AC35: 1.0416667 | AD35: 1.0416667 | AE35: 0.83333333 | AF35: 1 | AG35: 0.83333333 | AH35: 0.875 | AI35: 0.83333333 | AJ35: 0.83333333 | AK35: 0.875 | AM35: 30 | AO35: 49
A36: 35 | B36: 2025 | C36: 3 | D36: 90OV187 | E36: 31 | F36: 2 | G36: km-start | H36: 515805 | I36: 515985 | J36: 516085 | K36: 516251 | L36: 516411 | M36: 516611 | N36: 516766 | O36: 517040 | P36: 517235 | Q36: 517511 | R36: 517660 | S36: 517832 | T36: 517964 | U36: 518215 | V36: 518499 | W36: 518604 | X36: 518814 | Y36: 518957 | Z36: 519297 | AA36: 519520 | AB36: 519684 | AC36: 519831 | AD36: 520010 | AE36: 520267 | AF36: 520433 | AG36: 520631 | AH36: 520844 | AI36: 521090 | AJ36: 521466 | AK36: 521815
A37: 36 | B37: 2025 | C37: 3 | D37: 90OV187 | E37: 31 | F37: 2 | G37: km-end | H37: 515962 | I37: 516085 | J37: 516251 | K37: 516411 | L37: 516611 | M37: 516766 | N37: 517040 | O37: 517192 | P37: 517511 | Q37: 517660 | R37: 517832 | S37: 517964 | T37: 518215 | U37: 518499 | V37: 518604 | W37: 518806 | X37: 518955 | Y37: 519184 | Z37: 519516 | AA37: 519684 | AB37: 519831 | AC37: 520010 | AD37: 520267 | AE37: 520401 | AF37: 520622 | AG37: 520837 | AH37: 521067 | AI37: 521421 | AJ37: 521812 | AK37: 522058 | AP37: 1069.38 | AQ37: 18 | AS37: 5941
A38: 37 | B38: 2025 | C38: 3 | D38: 99HZ395 | E38: 31 | F38: 2 | G38: time-start | J38: 0.29166667 | K38: 0.29166667 | L38: 0.29166667 | M38: 0.29166667 | N38: 0.29166667 | O38: 0.29166667 | P38: 0.29166667 | Q38: 0.29166667 | R38: 0.29166667 | S38: 0.29166667 | T38: 0.29166667 | U38: 0.29166667 | V38: 0.29166667 | X38: 0.29166667 | Y38: 0.29166667 | Z38: 0.29166667 | AC38: 0.29166667 | AD38: 0.29166667 | AE38: 0.29166667 | AF38: 0.29166667 | AG38: 0.29166667 | AH38: 0.29166667 | AI38: 0.29166667 | AJ38: 0.29166667 | AL38: 0.29166667
A39: 38 | B39: 2025 | C39: 3 | D39: 99HZ395 | E39: 31 | F39: 2 | G39: time-end | J39: 0.75 | K39: 0.75 | L39: 0.75 | M39: 0.75 | N39: 0.75 | O39: 0.75 | P39: 0.75 | Q39: 0.75 | R39: 0.75 | S39: 0.75 | T39: 0.75 | U39: 0.75 | V39: 0.75 | X39: 0.75 | Y39: 0.75 | Z39: 0.75 | AC39: 0.75 | AD39: 0.75 | AE39: 0.75 | AF39: 0.75 | AG39: 0.75 | AH39: 0.75 | AI39: 0.75 | AJ39: 0.75 | AL39: 0.75 | AM39: 25
A40: 39 | B40: 2025 | C40: 3 | D40: 99HZ395 | E40: 31 | F40: 2 | G40: km-start | J40: 775300 | K40: 775503 | L40: 775655 | M40: 775789 | N40: 775942 | O40: 776086 | P40: 776235 | Q40: 776460 | R40: 776656 | S40: 776898 | T40: 777064 | U40: 777269 | V40: 777397 | X40: 777578 | Y40: 777742 | Z40: 777879 | AC40: 778197 | AD40: 778309 | AE40: 778440 | AF40: 778585 | AG40: 778729 | AH40: 778925 | AI40: 779068 | AJ40: 779265 | AL40: 779535
...

Sheet log_ipcs
A1: # | B1: ID | C1: contract no | D1: no | E1: start | F1: end | G1: Name | H1: Calculated | I1: Deduction | J1: IPC log | K1: Diff | M1: actual
A2: {=_xlfn.SEQUENCE(COUNTA(B:B)-1)} -> 1 | B2: {=_xlfn.DROP(_xlfn.UNIQUE(TEXT(_xlfn._TRO_TRAILING(quantities!D:D),"000")&"-"&TEXT(_xlfn._TRO_TRAILING(quantities!E:E),"000")),1)} -> 030-001 | C2: {=_xlfn.NUMBERVALUE(LEFT(_xlfn.ANCHORARRAY(B2),FIND("-",_xlfn.ANCHORARRAY(B2))-1))} -> 30 | D2: {=_xlfn.NUMBERVALUE(MID(_xlfn.ANCHORARRAY(B2),FIND("-",_xlfn.ANCHORARRAY(B2))+1,4))} -> 1 | E2: {=_xlfn.XLOOKUP(B2,old_ipc_dates!F:F,old_ipc_dates!B:B,IF(D2=1,_xlfn.XLOOKUP(C2,log_contracts!B:B,log_contracts!D:D,,0),_xlfn.XLOOKUP(1,($C1:C$18=C2)*($D1:D$18=D2-1),$F1:F$18+1,,0)),0)} -> 45658 | F2: =_xlfn.XLOOKUP(B2,old_ipc_dates!F:F,old_ipc_dates!C:C,EOMONTH(E2,0),0) -> 45688 | G2: {=_xlfn.XLOOKUP(_xlfn.ANCHORARRAY(C2),log_contracts!B:B,log_contracts!E:E,,0)} -> NAR TRANSPORT SERVICES MMC | H2: {=SUM(_xlfn._xlws.FILTER(_xlfn._TRO_TRAILING(quantities!L:L),(_xlfn._TRO_TRAILING(quantities!D:D)=C2)*(_xlfn._TRO_TRAILING(quantities!E:E)=D2)))} -> 1833.3333 | J2: =SUMIFS( INDIRECT("'[S2 Subcon IPC Log.xlsx]Subcon IPC Log'!"&"$O:$O"), INDIRECT("'[S2 Subcon IPC Log.xlsx]Subcon IPC Log'!"&"$C:$C"), "KLN-SPP2-"&_xlfn.XLOOKUP(C2,log_contracts!B:B,log_contracts!C:C)&"-"&TEXT(C2,"000"), INDIRECT("'[S2 Subcon IPC Log.xlsx]Subcon IPC Log'!"&"$D:$D"), "<="&D2) -> #REF! | K2: {=ROUND(_xlfn.DROP(_xlfn._TRO_TRAILING(H:H)-_xlfn._TRO_TRAILING(J:J),1),0)} -> #REF!
A3: 2 | B3: 031-001 | C3: 31 | D3: 1 | E3: {=_xlfn.XLOOKUP(B3,old_ipc_dates!F:F,old_ipc_dates!B:B,IF(D3=1,_xlfn.XLOOKUP(C3,log_contracts!B:B,log_contracts!D:D,,0),_xlfn.XLOOKUP(1,($C2:C$18=C3)*($D2:D$18=D3-1),$F2:F$18+1,,0)),0)} -> 45693 | F3: =_xlfn.XLOOKUP(B3,old_ipc_dates!F:F,old_ipc_dates!C:C,EOMONTH(E3,0),0) -> 45716 | G3: NAR TRANSPORT SERVICES MMC | H3: {=SUM(_xlfn._xlws.FILTER(_xlfn._TRO_TRAILING(quantities!L:L),(_xlfn._TRO_TRAILING(quantities!D:D)=C3)*(_xlfn._TRO_TRAILING(quantities!E:E)=D3)))} -> 11283.422 | J3: =SUMIFS( INDIRECT("'[S2 Subcon IPC Log.xlsx]Subcon IPC Log'!"&"$O:$O"), INDIRECT("'[S2 Subcon IPC Log.xlsx]Subcon IPC Log'!"&"$C:$C"), "KLN-SPP2-"&_xlfn.XLOOKUP(C3,log_contracts!B:B,log_contracts!C:C)&"-"&TEXT(C3,"000"), INDIRECT("'[S2 Subcon IPC Log.xlsx]Subcon IPC Log'!"&"$D:$D"), D3) -> #REF! | K3: #REF!
A4: 3 | B4: 046-001 | C4: 46 | D4: 1 | E4: {=_xlfn.XLOOKUP(B4,old_ipc_dates!F:F,old_ipc_dates!B:B,IF(D4=1,_xlfn.XLOOKUP(C4,log_contracts!B:B,log_contracts!D:D,,0),_xlfn.XLOOKUP(1,($C3:C$18=C4)*($D3:D$18=D4-1),$F3:F$18+1,,0)),0)} -> 45778 | F4: =_xlfn.XLOOKUP(B4,old_ipc_dates!F:F,old_ipc_dates!C:C,EOMONTH(E4,0),0) -> 45808 | G4: HARDCORE CONSTRUCTION AND EQUIPMENT | H4: {=SUM(_xlfn._xlws.FILTER(_xlfn._TRO_TRAILING(quantities!L:L),(_xlfn._TRO_TRAILING(quantities!D:D)=C4)*(_xlfn._TRO_TRAILING(quantities!E:E)=D4)))} -> 1714.2857 | J4: =SUMIFS( INDIRECT("'[S2 Subcon IPC Log.xlsx]Subcon IPC Log'!"&"$O:$O"), INDIRECT("'[S2 Subcon IPC Log.xlsx]Subcon IPC Log'!"&"$C:$C"), "KLN-SPP2-"&_xlfn.XLOOKUP(C4,log_contracts!B:B,log_contracts!C:C)&"-"&TEXT(C4,"000"), INDIRECT("'[S2 Subcon IPC Log.xlsx]Subcon IPC Log'!"&"$D:$D"), D4) -> #REF! | K4: #REF!
A5: 4 | B5: 050-001 | C5: 50 | D5: 1 | E5: {=_xlfn.XLOOKUP(B5,old_ipc_dates!F:F,old_ipc_dates!B:B,IF(D5=1,_xlfn.XLOOKUP(C5,log_contracts!B:B,log_contracts!D:D,,0),_xlfn.XLOOKUP(1,($C4:C$18=C5)*($D4:D$18=D5-1),$F4:F$18+1,,0)),0)} -> 45809 | F5: =_xlfn.XLOOKUP(B5,old_ipc_dates!F:F,old_ipc_dates!C:C,EOMONTH(E5,0),0) -> 45838 | G5: LOFT CONSTRUCTION | H5: {=SUM(_xlfn._xlws.FILTER(_xlfn._TRO_TRAILING(quantities!L:L),(_xlfn._TRO_TRAILING(quantities!D:D)=C5)*(_xlfn._TRO_TRAILING(quantities!E:E)=D5)))} -> 8750 | J5: =SUMIFS( INDIRECT("'[S2 Subcon IPC Log.xlsx]Subcon IPC Log'!"&"$O:$O"), INDIRECT("'[S2 Subcon IPC Log.xlsx]Subcon IPC Log'!"&"$C:$C"), "KLN-SPP2-"&_xlfn.XLOOKUP(C5,log_contracts!B:B,log_contracts!C:C)&"-"&TEXT(C5,"000"), INDIRECT("'[S2 Subcon IPC Log.xlsx]Subcon IPC Log'!"&"$D:$D"), D5) -> #REF! | K5: #REF!
A6: 5 | B6: 051-001 | C6: 51 | D6: 1 | E6: {=_xlfn.XLOOKUP(B6,old_ipc_dates!F:F,old_ipc_dates!B:B,IF(D6=1,_xlfn.XLOOKUP(C6,log_contracts!B:B,log_contracts!D:D,,0),_xlfn.XLOOKUP(1,($C5:C$18=C6)*($D5:D$18=D6-1),$F5:F$18+1,,0)),0)} -> 45761 | F6: =_xlfn.XLOOKUP(B6,old_ipc_dates!F:F,old_ipc_dates!C:C,EOMONTH(E6,0),0) -> 45777 | G6: INTERMAK GROUP MMC | H6: {=SUM(_xlfn._xlws.FILTER(_xlfn._TRO_TRAILING(quantities!L:L),(_xlfn._TRO_TRAILING(quantities!D:D)=C6)*(_xlfn._TRO_TRAILING(quantities!E:E)=D6)))} -> 3700 | J6: =SUMIFS( INDIRECT("'[S2 Subcon IPC Log.xlsx]Subcon IPC Log'!"&"$O:$O"), INDIRECT("'[S2 Subcon IPC Log.xlsx]Subcon IPC Log'!"&"$C:$C"), "KLN-SPP2-"&_xlfn.XLOOKUP(C6,log_contracts!B:B,log_contracts!C:C)&"-"&TEXT(C6,"000"), INDIRECT("'[S2 Subcon IPC Log.xlsx]Subcon IPC Log'!"&"$D:$D"), D6) -> #REF! | K6: #REF!
A7: 6 | B7: 052-001 | C7: 52 | D7: 1 | E7: {=_xlfn.XLOOKUP(B7,old_ipc_dates!F:F,old_ipc_dates!B:B,IF(D7=1,_xlfn.XLOOKUP(C7,log_contracts!B:B,log_contracts!D:D,,0),_xlfn.XLOOKUP(1,($C6:C$18=C7)*($D6:D$18=D7-1),$F6:F$18+1,,0)),0)} -> 45762 | F7: =_xlfn.XLOOKUP(B7,old_ipc_dates!F:F,old_ipc_dates!C:C,EOMONTH(E7,0),0) -> 45777 | G7: DTS MMC | H7: {=SUM(_xlfn._xlws.FILTER(_xlfn._TRO_TRAILING(quantities!L:L),(_xlfn._TRO_TRAILING(quantities!D:D)=C7)*(_xlfn._TRO_TRAILING(quantities!E:E)=D7)))} -> 6262.5 | J7: =SUMIFS( INDIRECT("'[S2 Subcon IPC Log.xlsx]Subcon IPC Log'!"&"$O:$O"), INDIRECT("'[S2 Subcon IPC Log.xlsx]Subcon IPC Log'!"&"$C:$C"), "KLN-SPP2-"&_xlfn.XLOOKUP(C7,log_contracts!B:B,log_contracts!C:C)&"-"&TEXT(C7,"000"), INDIRECT("'[S2 Subcon IPC Log.xlsx]Subcon IPC Log'!"&"$D:$D"), D7) -> #REF! | K7: #REF!
A8: 7 | B8: 065-001 | C8: 65 | D8: 1 | E8: {=_xlfn.XLOOKUP(B8,old_ipc_dates!F:F,old_ipc_dates!B:B,IF(D8=1,_xlfn.XLOOKUP(C8,log_contracts!B:B,log_contracts!D:D,,0),_xlfn.XLOOKUP(1,($C7:C$18=C8)*($D7:D$18=D8-1),$F7:F$18+1,,0)),0)} -> 45778 | F8: =_xlfn.XLOOKUP(B8,old_ipc_dates!F:F,old_ipc_dates!C:C,EOMONTH(E8,0),0) -> 45808 | G8: ETIBAR MAMMADOV | H8: {=SUM(_xlfn._xlws.FILTER(_xlfn._TRO_TRAILING(quantities!L:L),(_xlfn._TRO_TRAILING(quantities!D:D)=C8)*(_xlfn._TRO_TRAILING(quantities!E:E)=D8)))} -> 8446.3343 | J8: =SUMIFS( INDIRECT("'[S2 Subcon IPC Log.xlsx]Subcon IPC Log'!"&"$O:$O"), INDIRECT("'[S2 Subcon IPC Log.xlsx]Subcon IPC Log'!"&"$C:$C"), "KLN-SPP2-"&_xlfn.XLOOKUP(C8,log_contracts!B:B,log_contracts!C:C)&"-"&TEXT(C8,"000"), INDIRECT("'[S2 Subcon IPC Log.xlsx]Subcon IPC Log'!"&"$D:$D"), D8) -> #REF! | K8: #REF!
A9: 8 | B9: 085-001 | C9: 85 | D9: 1 | E9: {=_xlfn.XLOOKUP(B9,old_ipc_dates!F:F,old_ipc_dates!B:B,IF(D9=1,_xlfn.XLOOKUP(C9,log_contracts!B:B,log_contracts!D:D,,0),_xlfn.XLOOKUP(1,($C8:C$18=C9)*($D8:D$18=D9-1),$F8:F$18+1,,0)),0)} -> 45824 | F9: =_xlfn.XLOOKUP(B9,old_ipc_dates!F:F,old_ipc_dates!C:C,EOMONTH(E9,0),0) -> 45838 | G9: BABEK ALBANDOV | H9: {=SUM(_xlfn._xlws.FILTER(_xlfn._TRO_TRAILING(quantities!L:L),(_xlfn._TRO_TRAILING(quantities!D:D)=C9)*(_xlfn._TRO_TRAILING(quantities!E:E)=D9)))} -> 7857.168 | J9: =SUMIFS( INDIRECT("'[S2 Subcon IPC Log.xlsx]Subcon IPC Log'!"&"$O:$O"), INDIRECT("'[S2 Subcon IPC Log.xlsx]Subcon IPC Log'!"&"$C:$C"), "KLN-SPP2-"&_xlfn.XLOOKUP(C9,log_contracts!B:B,log_contracts!C:C)&"-"&TEXT(C9,"000"), INDIRECT("'[S2 Subcon IPC Log.xlsx]Subcon IPC Log'!"&"$D:$D"), D9) -> #REF! | K9: #REF!
A10: 9 | B10: 094-001 | C10: 94 | D10: 1 | E10: {=_xlfn.XLOOKUP(B10,old_ipc_dates!F:F,old_ipc_dates!B:B,IF(D10=1,_xlfn.XLOOKUP(C10,log_contracts!B:B,log_contracts!D:D,,0),_xlfn.XLOOKUP(1,($C9:C$18=C10)*($D9:D$18=D10-1),$F9:F$18+1,,0)),0)} -> 45809 | F10: =_xlfn.XLOOKUP(B10,old_ipc_dates!F:F,old_ipc_dates!C:C,EOMONTH(E10,0),0) -> 45838 | G10: XANIM ABDULLAYEVA | H10: {=SUM(_xlfn._xlws.FILTER(_xlfn._TRO_TRAILING(quantities!L:L),(_xlfn._TRO_TRAILING(quantities!D:D)=C10)*(_xlfn._TRO_TRAILING(quantities!E:E)=D10)))} -> 3500 | J10: =SUMIFS( INDIRECT("'[S2 Subcon IPC Log.xlsx]Subcon IPC Log'!"&"$O:$O"), INDIRECT("'[S2 Subcon IPC Log.xlsx]Subcon IPC Log'!"&"$C:$C"), "KLN-SPP2-"&_xlfn.XLOOKUP(C10,log_contracts!B:B,log_contracts!C:C)&"-"&TEXT(C10,"000"), INDIRECT("'[S2 Subcon IPC Log.xlsx]Subcon IPC Log'!"&"$D:$D"), D10) -> #REF! | K10: #REF!
A11: 10 | B11: 095-001 | C11: 95 | D11: 1 | E11: {=_xlfn.XLOOKUP(B11,old_ipc_dates!F:F,old_ipc_dates!B:B,IF(D11=1,_xlfn.XLOOKUP(C11,log_contracts!B:B,log_contracts!D:D,,0),_xlfn.XLOOKUP(1,($C10:C$18=C11)*($D10:D$18=D11-1),$F10:F$18+1,,0)),0)} -> 45851 | F11: =_xlfn.XLOOKUP(B11,old_ipc_dates!F:F,old_ipc_dates!C:C,EOMONTH(E11,0),0) -> 45869 | G11: IBRAHIM XALILOV | H11: {=SUM(_xlfn._xlws.FILTER(_xlfn._TRO_TRAILING(quantities!L:L),(_xlfn._TRO_TRAILING(quantities!D:D)=C11)*(_xlfn._TRO_TRAILING(quantities!E:E)=D11)))} -> 4714.215 | J11: =SUMIFS( INDIRECT("'[S2 Subcon IPC Log.xlsx]Subcon IPC Log'!"&"$O:$O"), INDIRECT("'[S2 Subcon IPC Log.xlsx]Subcon IPC Log'!"&"$C:$C"), "KLN-SPP2-"&_xlfn.XLOOKUP(C11,log_contracts!B:B,log_contracts!C:C)&"-"&TEXT(C11,"000"), INDIRECT("'[S2 Subcon IPC Log.xlsx]Subcon IPC Log'!"&"$D:$D"), D11) -> #REF! | K11: #REF!
A12: 11 | B12: 098-001 | C12: 98 | D12: 1 | E12: {=_xlfn.XLOOKUP(B12,old_ipc_dates!F:F,old_ipc_dates!B:B,IF(D12=1,_xlfn.XLOOKUP(C12,log_contracts!B:B,log_contracts!D:D,,0),_xlfn.XLOOKUP(1,($C11:C$18=C12)*($D11:D$18=D12-1),$F11:F$18+1,,0)),0)} -> 45858 | F12: =_xlfn.XLOOKUP(B12,old_ipc_dates!F:F,old_ipc_dates!C:C,EOMONTH(E12,0),0) -> 45869 | G12: HACIAGA KERIMOV | H12: {=SUM(_xlfn._xlws.FILTER(_xlfn._TRO_TRAILING(quantities!L:L),(_xlfn._TRO_TRAILING(quantities!D:D)=C12)*(_xlfn._TRO_TRAILING(quantities!E:E)=D12)))} -> 1285.68 | J12: =SUMIFS( INDIRECT("'[S2 Subcon IPC Log.xlsx]Subcon IPC Log'!"&"$O:$O"), INDIRECT("'[S2 Subcon IPC Log.xlsx]Subcon IPC Log'!"&"$C:$C"), "KLN-SPP2-"&_xlfn.XLOOKUP(C12,log_contracts!B:B,log_contracts!C:C)&"-"&TEXT(C12,"000"), INDIRECT("'[S2 Subcon IPC Log.xlsx]Subcon IPC Log'!"&"$D:$D"), D12) -> #REF! | K12: #REF!
A13: 12 | B13: 099-001 | C13: 99 | D13: 1 | E13: {=_xlfn.XLOOKUP(B13,old_ipc_dates!F:F,old_ipc_dates!B:B,IF(D13=1,_xlfn.XLOOKUP(C13,log_contracts!B:B,log_contracts!D:D,,0),_xlfn.XLOOKUP(1,($C12:C$18=C13)*($D12:D$18=D13-1),$F12:F$18+1,,0)),0)} -> 45859 | F13: =_xlfn.XLOOKUP(B13,old_ipc_dates!F:F,old_ipc_dates!C:C,EOMONTH(E13,0),0) -> 45869 | G13: YUSIF MAHARRAMOV | H13: {=SUM(_xlfn._xlws.FILTER(_xlfn._TRO_TRAILING(quantities!L:L),(_xlfn._TRO_TRAILING(quantities!D:D)=C13)*(_xlfn._TRO_TRAILING(quantities!E:E)=D13)))} -> 1250 | J13: =SUMIFS( INDIRECT("'[S2 Subcon IPC Log.xlsx]Subcon IPC Log'!"&"$O:$O"), INDIRECT("'[S2 Subcon IPC Log.xlsx]Subcon IPC Log'!"&"$C:$C"), "KLN-SPP2-"&_xlfn.XLOOKUP(C13,log_contracts!B:B,log_contracts!C:C)&"-"&TEXT(C13,"000"), INDIRECT("'[S2 Subcon IPC Log.xlsx]Subcon IPC Log'!"&"$D:$D"), D13) -> #REF! | K13: #REF!
A14: 13 | B14: 100-001 | C14: 100 | D14: 1 | E14: {=_xlfn.XLOOKUP(B14,old_ipc_dates!F:F,old_ipc_dates!B:B,IF(D14=1,_xlfn.XLOOKUP(C14,log_contracts!B:B,log_contracts!D:D,,0),_xlfn.XLOOKUP(1,($C13:C$18=C14)*($D13:D$18=D14-1),$F13:F$18+1,,0)),0)} -> 45861 | F14: =_xlfn.XLOOKUP(B14,old_ipc_dates!F:F,old_ipc_dates!C:C,EOMONTH(E14,0),0) -> 45869 | G14: RUSLAN HUSEYNOV | H14: {=SUM(_xlfn._xlws.FILTER(_xlfn._TRO_TRAILING(quantities!L:L),(_xlfn._TRO_TRAILING(quantities!D:D)=C14)*(_xlfn._TRO_TRAILING(quantities!E:E)=D14)))} -> 1767.8571 | J14: =SUMIFS( INDIRECT("'[S2 Subcon IPC Log.xlsx]Subcon IPC Log'!"&"$O:$O"), INDIRECT("'[S2 Subcon IPC Log.xlsx]Subcon IPC Log'!"&"$C:$C"), "KLN-SPP2-"&_xlfn.XLOOKUP(C14,log_contracts!B:B,log_contracts!C:C)&"-"&TEXT(C14,"000"), INDIRECT("'[S2 Subcon IPC Log.xlsx]Subcon IPC Log'!"&"$D:$D"), D14) -> #REF! | K14: #REF!
... A19: 18 | B19: 163-001 | C19: 163 | D19: 1 | E19: {=_xlfn.XLOOKUP(B19,old_ipc_dates!F:F,old_ipc_dates!B:B,IF(D19=1,_xlfn.XLOOKUP(C19,log_contracts!B:B,log_contracts!D:D,,0),_xlfn.XLOOKUP(1,($C18:C$18=C19)*($D18:D$18=D19-1),$F18:F$18+1,,0)),0)} -> 46035 | F19: =_xlfn.XLOOKUP(B19,old_ipc_dates!F:F,old_ipc_dates!C:C,EOMONTH(E19,0),0) -> 46053 | G19: Əsgərov Yaşar | H19: {=SUM(_xlfn._xlws.FILTER(_xlfn._TRO_TRAILING(quantities!L:L),(_xlfn._TRO_TRAILING(quantities!D:D)=C19)*(_xlfn._TRO_TRAILING(quantities!E:E)=D19)))} -> 2375 | J19: =SUMIFS( INDIRECT("'[S2 Subcon IPC Log.xlsx]Subcon IPC Log'!"&"$O:$O"), INDIRECT("'[S2 Subcon IPC Log.xlsx]Subcon IPC Log'!"&"$C:$C"), "KLN-SPP2-"&_xlfn.XLOOKUP(C19,log_contracts!B:B,log_contracts!C:C)&"-"&TEXT(C19,"000"), INDIRECT("'[S2 Subcon IPC Log.xlsx]Subcon IPC Log'!"&"$D:$D"), D19) -> #REF! | K19: #REF!
A20: 19 | B20: 164-001 | C20: 164 | D20: 1 | E20: {=_xlfn.XLOOKUP(B20,old_ipc_dates!F:F,old_ipc_dates!B:B,IF(D20=1,_xlfn.XLOOKUP(C20,log_contracts!B:B,log_contracts!D:D,,0),_xlfn.XLOOKUP(1,($C$18:C19=C20)*($D$18:D19=D20-1),$F$18:F19+1,,0)),0)} -> 46035 | F20: =_xlfn.XLOOKUP(B20,old_ipc_dates!F:F,old_ipc_dates!C:C,EOMONTH(E20,0),0) -> 46053 | G20: Əliyev Fizuli | H20: {=SUM(_xlfn._xlws.FILTER(_xlfn._TRO_TRAILING(quantities!L:L),(_xlfn._TRO_TRAILING(quantities!D:D)=C20)*(_xlfn._TRO_TRAILING(quantities!E:E)=D20)))} -> 6875 | J20: =SUMIFS( INDIRECT("'[S2 Subcon IPC Log.xlsx]Subcon IPC Log'!"&"$O:$O"), INDIRECT("'[S2 Subcon IPC Log.xlsx]Subcon IPC Log'!"&"$C:$C"), "KLN-SPP2-"&_xlfn.XLOOKUP(C20,log_contracts!B:B,log_contracts!C:C)&"-"&TEXT(C20,"000"), INDIRECT("'[S2 Subcon IPC Log.xlsx]Subcon IPC Log'!"&"$D:$D"), D20) -> #REF! | K20: #REF!
A21: 20 | B21: 172-001 | C21: 172 | D21: 1 | E21: {=_xlfn.XLOOKUP(B21,old_ipc_dates!F:F,old_ipc_dates!B:B,IF(D21=1,_xlfn.XLOOKUP(C21,log_contracts!B:B,log_contracts!D:D,,0),_xlfn.XLOOKUP(1,($C$18:C20=C21)*($D$18:D20=D21-1),$F$18:F20+1,,0)),0)} -> 46034 | F21: =_xlfn.XLOOKUP(B21,old_ipc_dates!F:F,old_ipc_dates!C:C,EOMONTH(E21,0),0) -> 46053 | G21: Mahmudov Rüstəm | H21: {=SUM(_xlfn._xlws.FILTER(_xlfn._TRO_TRAILING(quantities!L:L),(_xlfn._TRO_TRAILING(quantities!D:D)=C21)*(_xlfn._TRO_TRAILING(quantities!E:E)=D21)))} -> 3732.1429 | J21: =SUMIFS( INDIRECT("'[S2 Subcon IPC Log.xlsx]Subcon IPC Log'!"&"$O:$O"), INDIRECT("'[S2 Subcon IPC Log.xlsx]Subcon IPC Log'!"&"$C:$C"), "KLN-SPP2-"&_xlfn.XLOOKUP(C21,log_contracts!B:B,log_contracts!C:C)&"-"&TEXT(C21,"000"), INDIRECT("'[S2 Subcon IPC Log.xlsx]Subcon IPC Log'!"&"$D:$D"), D21) -> #REF! | K21: #REF!
A22: 21 | B22: 173-001 | C22: 173 | D22: 1 | E22: {=_xlfn.XLOOKUP(B22,old_ipc_dates!F:F,old_ipc_dates!B:B,IF(D22=1,_xlfn.XLOOKUP(C22,log_contracts!B:B,log_contracts!D:D,,0),_xlfn.XLOOKUP(1,($C$18:C21=C22)*($D$18:D21=D22-1),$F$18:F21+1,,0)),0)} -> 46054 | F22: =_xlfn.XLOOKUP(B22,old_ipc_dates!F:F,old_ipc_dates!C:C,EOMONTH(E22,0),0) -> 46081 | G22: Hüseynov Pərviz | H22: {=SUM(_xlfn._xlws.FILTER(_xlfn._TRO_TRAILING(quantities!L:L),(_xlfn._TRO_TRAILING(quantities!D:D)=C22)*(_xlfn._TRO_TRAILING(quantities!E:E)=D22)))} -> 10357.143 | J22: =SUMIFS( INDIRECT("'[S2 Subcon IPC Log.xlsx]Subcon IPC Log'!"&"$O:$O"), INDIRECT("'[S2 Subcon IPC Log.xlsx]Subcon IPC Log'!"&"$C:$C"), "KLN-SPP2-"&_xlfn.XLOOKUP(C22,log_contracts!B:B,log_contracts!C:C)&"-"&TEXT(C22,"000"), INDIRECT("'[S2 Subcon IPC Log.xlsx]Subcon IPC Log'!"&"$D:$D"), D22) -> #REF! | K22: #REF!
